[2024-09-02 08:52:12,706: INFO: main: This is use to test logging messages]
[2024-09-07 18:31:30,460: INFO: main: >>>>>> stage Data Ingestion stage started <<<<<<<<<]
[2024-09-07 18:31:30,461: ERROR: main: name 'BoxValueError' is not defined]
Traceback (most recent call last):
  File "/Users/kjaggav1/Library/CloudStorage/OneDrive-JCPenney/myworkspace/practice/foodclassification/src/foodclassification/utils/common.py", line 17, in read_yaml
    content = yaml.safe_load(yaml_file)
              ^^^^
NameError: name 'yaml' is not defined

During handling of the above exception, another exception occurred:

Traceback (most recent call last):
  File "/Users/kjaggav1/Library/CloudStorage/OneDrive-JCPenney/myworkspace/practice/foodclassification/main.py", line 11, in <module>
    obj.main()
  File "/Users/kjaggav1/Library/CloudStorage/OneDrive-JCPenney/myworkspace/practice/foodclassification/src/foodclassification/pipeline/stage_01_data_ingestion.py", line 12, in main
    config = ConfigurationManager()
             ^^^^^^^^^^^^^^^^^^^^^^
  File "/Users/kjaggav1/Library/CloudStorage/OneDrive-JCPenney/myworkspace/practice/foodclassification/src/foodclassification/config/configuration.py", line 11, in __init__
    self.config = read_yaml(config_filepath)
                  ^^^^^^^^^^^^^^^^^^^^^^^^^^
  File "/Users/kjaggav1/Library/CloudStorage/OneDrive-JCPenney/myworkspace/practice/foodclassification/.venv/lib/python3.12/site-packages/ensure/main.py", line 872, in __call__
    return_val = self.f(*args, **kwargs)
                 ^^^^^^^^^^^^^^^^^^^^^^^
  File "/Users/kjaggav1/Library/CloudStorage/OneDrive-JCPenney/myworkspace/practice/foodclassification/src/foodclassification/utils/common.py", line 20, in read_yaml
    except BoxValueError:
           ^^^^^^^^^^^^^
NameError: name 'BoxValueError' is not defined. Did you mean: 'ValueError'?
[2024-09-07 18:31:55,163: INFO: main: >>>>>> stage Data Ingestion stage started <<<<<<<<<]
[2024-09-07 18:31:55,163: ERROR: main: name 'BoxValueError' is not defined]
Traceback (most recent call last):
  File "/Users/kjaggav1/Library/CloudStorage/OneDrive-JCPenney/myworkspace/practice/foodclassification/src/foodclassification/utils/common.py", line 17, in read_yaml
    content = yaml.safe_load(yaml_file)
              ^^^^
NameError: name 'yaml' is not defined

During handling of the above exception, another exception occurred:

Traceback (most recent call last):
  File "/Users/kjaggav1/Library/CloudStorage/OneDrive-JCPenney/myworkspace/practice/foodclassification/main.py", line 11, in <module>
    obj.main()
  File "/Users/kjaggav1/Library/CloudStorage/OneDrive-JCPenney/myworkspace/practice/foodclassification/src/foodclassification/pipeline/stage_01_data_ingestion.py", line 12, in main
    config = ConfigurationManager()
             ^^^^^^^^^^^^^^^^^^^^^^
  File "/Users/kjaggav1/Library/CloudStorage/OneDrive-JCPenney/myworkspace/practice/foodclassification/src/foodclassification/config/configuration.py", line 11, in __init__
    self.config = read_yaml(config_filepath)
                  ^^^^^^^^^^^^^^^^^^^^^^^^^^
  File "/Users/kjaggav1/Library/CloudStorage/OneDrive-JCPenney/myworkspace/practice/foodclassification/.venv/lib/python3.12/site-packages/ensure/main.py", line 872, in __call__
    return_val = self.f(*args, **kwargs)
                 ^^^^^^^^^^^^^^^^^^^^^^^
  File "/Users/kjaggav1/Library/CloudStorage/OneDrive-JCPenney/myworkspace/practice/foodclassification/src/foodclassification/utils/common.py", line 20, in read_yaml
    except BoxValueError:
           ^^^^^^^^^^^^^
NameError: name 'BoxValueError' is not defined. Did you mean: 'ValueError'?
[2024-09-07 18:35:33,311: INFO: main: >>>>>> stage Data Ingestion stage started <<<<<<<<<]
[2024-09-07 18:35:33,311: ERROR: main: name 'BoxValueError' is not defined]
Traceback (most recent call last):
  File "/Users/kjaggav1/Library/CloudStorage/OneDrive-JCPenney/myworkspace/practice/foodclassification/src/foodclassification/utils/common.py", line 17, in read_yaml
    content = yaml.safe_load(yaml_file)
              ^^^^
NameError: name 'yaml' is not defined

During handling of the above exception, another exception occurred:

Traceback (most recent call last):
  File "/Users/kjaggav1/Library/CloudStorage/OneDrive-JCPenney/myworkspace/practice/foodclassification/main.py", line 11, in <module>
    obj.main()
  File "/Users/kjaggav1/Library/CloudStorage/OneDrive-JCPenney/myworkspace/practice/foodclassification/src/foodclassification/pipeline/stage_01_data_ingestion.py", line 12, in main
    config = ConfigurationManager()
             ^^^^^^^^^^^^^^^^^^^^^^
  File "/Users/kjaggav1/Library/CloudStorage/OneDrive-JCPenney/myworkspace/practice/foodclassification/src/foodclassification/config/configuration.py", line 11, in __init__
    self.config = read_yaml(config_filepath)
                  ^^^^^^^^^^^^^^^^^^^^^^^^^^
  File "/Users/kjaggav1/Library/CloudStorage/OneDrive-JCPenney/myworkspace/practice/foodclassification/.venv/lib/python3.12/site-packages/ensure/main.py", line 872, in __call__
    return_val = self.f(*args, **kwargs)
                 ^^^^^^^^^^^^^^^^^^^^^^^
  File "/Users/kjaggav1/Library/CloudStorage/OneDrive-JCPenney/myworkspace/practice/foodclassification/src/foodclassification/utils/common.py", line 20, in read_yaml
    except BoxValueError:
           ^^^^^^^^^^^^^
NameError: name 'BoxValueError' is not defined. Did you mean: 'ValueError'?
[2024-09-07 18:37:17,450: INFO: main: >>>>>> stage Data Ingestion stage started <<<<<<<<<]
[2024-09-07 18:37:17,451: ERROR: main: name 'logger' is not defined]
Traceback (most recent call last):
  File "/Users/kjaggav1/Library/CloudStorage/OneDrive-JCPenney/myworkspace/practice/foodclassification/main.py", line 11, in <module>
    obj.main()
  File "/Users/kjaggav1/Library/CloudStorage/OneDrive-JCPenney/myworkspace/practice/foodclassification/src/foodclassification/pipeline/stage_01_data_ingestion.py", line 12, in main
    config = ConfigurationManager()
             ^^^^^^^^^^^^^^^^^^^^^^
  File "/Users/kjaggav1/Library/CloudStorage/OneDrive-JCPenney/myworkspace/practice/foodclassification/src/foodclassification/config/configuration.py", line 11, in __init__
    self.config = read_yaml(config_filepath)
                  ^^^^^^^^^^^^^^^^^^^^^^^^^^
  File "/Users/kjaggav1/Library/CloudStorage/OneDrive-JCPenney/myworkspace/practice/foodclassification/.venv/lib/python3.12/site-packages/ensure/main.py", line 872, in __call__
    return_val = self.f(*args, **kwargs)
                 ^^^^^^^^^^^^^^^^^^^^^^^
  File "/Users/kjaggav1/Library/CloudStorage/OneDrive-JCPenney/myworkspace/practice/foodclassification/src/foodclassification/utils/common.py", line 23, in read_yaml
    raise e
  File "/Users/kjaggav1/Library/CloudStorage/OneDrive-JCPenney/myworkspace/practice/foodclassification/src/foodclassification/utils/common.py", line 18, in read_yaml
    logger.info(f"yaml file: {path_to_yaml} loaded successfully")
    ^^^^^^
NameError: name 'logger' is not defined
[2024-09-07 18:39:15,928: INFO: main: >>>>>> stage Data Ingestion stage started <<<<<<<<<]
[2024-09-07 18:39:15,928: INFO: common: yaml file: config/config.yaml loaded successfully]
[2024-09-07 18:39:15,929: INFO: common: yaml file: params.yaml loaded successfully]
[2024-09-07 18:39:15,930: INFO: common: created directory at: artifacts]
[2024-09-07 18:39:15,930: INFO: common: created directory at: artifacts/data_ingestion]
[2024-09-07 18:39:15,930: ERROR: main: "'ConfigBox' object has no attribute 'object_key'"]
Traceback (most recent call last):
  File "box/box.py", line 593, in box.box.Box.__getitem__
KeyError: 'object_key'

The above exception was the direct cause of the following exception:

Traceback (most recent call last):
  File "box/box.py", line 632, in box.box.Box.__getattr__
  File "box/box.py", line 620, in box.box.Box.__getitem__
box.exceptions.BoxKeyError: "'object_key'"

During handling of the above exception, another exception occurred:

Traceback (most recent call last):
  File "box/box.py", line 634, in box.box.Box.__getattr__
AttributeError: 'ConfigBox' object has no attribute 'object_key'

The above exception was the direct cause of the following exception:

Traceback (most recent call last):
  File "box/config_box.py", line 29, in box.config_box.ConfigBox.__getattr__
  File "box/box.py", line 648, in box.box.Box.__getattr__
box.exceptions.BoxKeyError: "'ConfigBox' object has no attribute 'object_key'"

During handling of the above exception, another exception occurred:

Traceback (most recent call last):
  File "box/box.py", line 593, in box.box.Box.__getitem__
KeyError: 'object_key'

The above exception was the direct cause of the following exception:

Traceback (most recent call last):
  File "box/box.py", line 632, in box.box.Box.__getattr__
  File "box/box.py", line 620, in box.box.Box.__getitem__
box.exceptions.BoxKeyError: "'object_key'"

During handling of the above exception, another exception occurred:

Traceback (most recent call last):
  File "box/box.py", line 634, in box.box.Box.__getattr__
AttributeError: 'ConfigBox' object has no attribute 'object_key'

The above exception was the direct cause of the following exception:

Traceback (most recent call last):
  File "/Users/kjaggav1/Library/CloudStorage/OneDrive-JCPenney/myworkspace/practice/foodclassification/main.py", line 11, in <module>
    obj.main()
  File "/Users/kjaggav1/Library/CloudStorage/OneDrive-JCPenney/myworkspace/practice/foodclassification/src/foodclassification/pipeline/stage_01_data_ingestion.py", line 13, in main
    data_ingestion_config = config.get_data_ingestion_config()
                            ^^^^^^^^^^^^^^^^^^^^^^^^^^^^^^^^^^
  File "/Users/kjaggav1/Library/CloudStorage/OneDrive-JCPenney/myworkspace/practice/foodclassification/src/foodclassification/config/configuration.py", line 24, in get_data_ingestion_config
    object_key=config.object_key,
               ^^^^^^^^^^^^^^^^^
  File "box/config_box.py", line 31, in box.config_box.ConfigBox.__getattr__
  File "box/box.py", line 648, in box.box.Box.__getattr__
box.exceptions.BoxKeyError: "'ConfigBox' object has no attribute 'object_key'"
[2024-09-07 18:46:21,418: INFO: main: >>>>>> stage Data Ingestion stage started <<<<<<<<<]
[2024-09-07 18:46:21,419: INFO: common: yaml file: config/config.yaml loaded successfully]
[2024-09-07 18:46:21,421: INFO: common: yaml file: params.yaml loaded successfully]
[2024-09-07 18:46:21,421: INFO: common: created directory at: artifacts]
[2024-09-07 18:46:21,422: INFO: common: created directory at: artifacts/data_ingestion]
[2024-09-07 18:46:21,422: ERROR: main: "'ConfigBox' object has no attribute 'bucket_name'"]
Traceback (most recent call last):
  File "box/box.py", line 593, in box.box.Box.__getitem__
KeyError: 'bucket_name'

The above exception was the direct cause of the following exception:

Traceback (most recent call last):
  File "box/box.py", line 632, in box.box.Box.__getattr__
  File "box/box.py", line 620, in box.box.Box.__getitem__
box.exceptions.BoxKeyError: "'bucket_name'"

During handling of the above exception, another exception occurred:

Traceback (most recent call last):
  File "box/box.py", line 634, in box.box.Box.__getattr__
AttributeError: 'ConfigBox' object has no attribute 'bucket_name'

The above exception was the direct cause of the following exception:

Traceback (most recent call last):
  File "box/config_box.py", line 29, in box.config_box.ConfigBox.__getattr__
  File "box/box.py", line 648, in box.box.Box.__getattr__
box.exceptions.BoxKeyError: "'ConfigBox' object has no attribute 'bucket_name'"

During handling of the above exception, another exception occurred:

Traceback (most recent call last):
  File "box/box.py", line 593, in box.box.Box.__getitem__
KeyError: 'bucket_name'

The above exception was the direct cause of the following exception:

Traceback (most recent call last):
  File "box/box.py", line 632, in box.box.Box.__getattr__
  File "box/box.py", line 620, in box.box.Box.__getitem__
box.exceptions.BoxKeyError: "'bucket_name'"

During handling of the above exception, another exception occurred:

Traceback (most recent call last):
  File "box/box.py", line 634, in box.box.Box.__getattr__
AttributeError: 'ConfigBox' object has no attribute 'bucket_name'

The above exception was the direct cause of the following exception:

Traceback (most recent call last):
  File "/Users/kjaggav1/Library/CloudStorage/OneDrive-JCPenney/myworkspace/practice/foodclassification/main.py", line 11, in <module>
    obj.main()
  File "/Users/kjaggav1/Library/CloudStorage/OneDrive-JCPenney/myworkspace/practice/foodclassification/src/foodclassification/pipeline/stage_01_data_ingestion.py", line 13, in main
    data_ingestion_config = config.get_data_ingestion_config()
                            ^^^^^^^^^^^^^^^^^^^^^^^^^^^^^^^^^^
  File "/Users/kjaggav1/Library/CloudStorage/OneDrive-JCPenney/myworkspace/practice/foodclassification/src/foodclassification/config/configuration.py", line 27, in get_data_ingestion_config
    bucket_name=config.bucket_name,
                ^^^^^^^^^^^^^^^^^^
  File "box/config_box.py", line 31, in box.config_box.ConfigBox.__getattr__
  File "box/box.py", line 648, in box.box.Box.__getattr__
box.exceptions.BoxKeyError: "'ConfigBox' object has no attribute 'bucket_name'"
[2024-09-07 18:47:18,567: INFO: main: >>>>>> stage Data Ingestion stage started <<<<<<<<<]
[2024-09-07 18:47:18,567: INFO: common: yaml file: config/config.yaml loaded successfully]
[2024-09-07 18:47:18,569: INFO: common: yaml file: params.yaml loaded successfully]
[2024-09-07 18:47:18,569: INFO: common: created directory at: artifacts]
[2024-09-07 18:47:18,569: INFO: common: created directory at: artifacts/data_ingestion]
[2024-09-07 18:47:18,569: ERROR: main: 'AWS_ACCESS_KEY_ID']
Traceback (most recent call last):
  File "/Users/kjaggav1/Library/CloudStorage/OneDrive-JCPenney/myworkspace/practice/foodclassification/main.py", line 11, in <module>
    obj.main()
  File "/Users/kjaggav1/Library/CloudStorage/OneDrive-JCPenney/myworkspace/practice/foodclassification/src/foodclassification/pipeline/stage_01_data_ingestion.py", line 13, in main
    data_ingestion_config = config.get_data_ingestion_config()
                            ^^^^^^^^^^^^^^^^^^^^^^^^^^^^^^^^^^
  File "/Users/kjaggav1/Library/CloudStorage/OneDrive-JCPenney/myworkspace/practice/foodclassification/src/foodclassification/config/configuration.py", line 28, in get_data_ingestion_config
    access_key=os.environ['AWS_ACCESS_KEY_ID'],
               ~~~~~~~~~~^^^^^^^^^^^^^^^^^^^^^
  File "<frozen os>", line 714, in __getitem__
KeyError: 'AWS_ACCESS_KEY_ID'
[2024-09-07 18:47:50,875: INFO: main: >>>>>> stage Data Ingestion stage started <<<<<<<<<]
[2024-09-07 18:47:50,875: INFO: common: yaml file: config/config.yaml loaded successfully]
[2024-09-07 18:47:50,876: INFO: common: yaml file: params.yaml loaded successfully]
[2024-09-07 18:47:50,877: INFO: common: created directory at: artifacts]
[2024-09-07 18:47:50,877: INFO: common: created directory at: artifacts/data_ingestion]
[2024-09-07 18:48:12,593: INFO: data_ingestion: File 'foodclassification.zip' downloaded to 'artifacts/data_ingestion/data.zip'.]
[2024-09-07 18:48:15,951: INFO: main: >>>>>> stage Data Ingestion stage completed <<<<<<<<

x==============x]
[2024-09-08 22:30:57,967: INFO: common: yaml file: config/config.yaml loaded successfully]
[2024-09-08 22:30:57,971: INFO: common: yaml file: params.yaml loaded successfully]
[2024-09-08 22:30:57,973: INFO: common: created directory at: artifacts]
[2024-09-08 22:30:57,974: INFO: common: created directory at: artifacts/prepare_base_model]
[2024-09-08 22:33:20,251: INFO: common: yaml file: config/config.yaml loaded successfully]
[2024-09-08 22:33:20,253: INFO: common: yaml file: params.yaml loaded successfully]
[2024-09-08 22:33:20,254: INFO: common: created directory at: artifacts]
[2024-09-08 22:33:20,254: INFO: common: created directory at: artifacts/prepare_base_model]
[2024-09-08 22:34:18,640: INFO: common: yaml file: config/config.yaml loaded successfully]
[2024-09-08 22:34:18,642: INFO: common: yaml file: params.yaml loaded successfully]
[2024-09-08 22:34:18,643: INFO: common: created directory at: artifacts]
[2024-09-08 22:34:18,643: INFO: common: created directory at: artifacts/prepare_base_model]
[2024-09-08 22:35:07,221: INFO: common: yaml file: config/config.yaml loaded successfully]
[2024-09-08 22:35:07,223: INFO: common: yaml file: params.yaml loaded successfully]
[2024-09-08 22:35:07,224: INFO: common: created directory at: artifacts]
[2024-09-08 22:35:07,224: INFO: common: created directory at: artifacts/prepare_base_model]
[2024-09-08 22:49:15,573: INFO: common: yaml file: config/config.yaml loaded successfully]
[2024-09-08 22:49:15,574: INFO: common: yaml file: params.yaml loaded successfully]
[2024-09-08 22:49:15,575: INFO: common: created directory at: artifacts]
[2024-09-08 22:49:15,575: INFO: common: created directory at: artifacts/prepare_base_model]
[2024-09-09 15:28:41,832: INFO: common: yaml file: config/config.yaml loaded successfully]
[2024-09-09 15:28:41,833: INFO: common: yaml file: params.yaml loaded successfully]
[2024-09-09 15:28:41,834: INFO: common: created directory at: artifacts]
[2024-09-09 15:28:41,834: INFO: common: created directory at: artifacts/prepare_base_model]
[2024-09-09 15:28:42,008: WARNING: saving_api: You are saving your model as an HDF5 file via `model.save()` or `keras.saving.save_model(model)`. This file format is considered legacy. We recommend using instead the native Keras format, e.g. `model.save('my_model.keras')` or `keras.saving.save_model(model, 'my_model.keras')`. ]
[2024-09-09 15:28:42,065: WARNING: saving_api: You are saving your model as an HDF5 file via `model.save()` or `keras.saving.save_model(model)`. This file format is considered legacy. We recommend using instead the native Keras format, e.g. `model.save('my_model.keras')` or `keras.saving.save_model(model, 'my_model.keras')`. ]
[2024-09-09 23:12:16,879: INFO: main: >>>>>> stage Data Ingestion stage started <<<<<<<<<]
[2024-09-09 23:12:16,882: INFO: common: yaml file: config/config.yaml loaded successfully]
[2024-09-09 23:12:16,883: INFO: common: yaml file: params.yaml loaded successfully]
[2024-09-09 23:12:16,883: INFO: common: created directory at: artifacts]
[2024-09-09 23:12:16,883: INFO: common: created directory at: artifacts/data_ingestion]
[2024-09-09 23:12:43,111: INFO: data_ingestion: File 'foodclassification.zip' downloaded to 'artifacts/data_ingestion/data.zip'.]
[2024-09-09 23:12:47,522: INFO: main: >>>>>> stage Data Ingestion stage completed <<<<<<<<

x==============x]
[2024-09-09 23:12:47,522: INFO: main: ***************************]
[2024-09-09 23:12:47,523: INFO: main: >>>>>>>> stage Prepare base model started <<<<<<<<<<]
[2024-09-09 23:12:47,523: INFO: common: yaml file: config/config.yaml loaded successfully]
[2024-09-09 23:12:47,524: INFO: common: yaml file: params.yaml loaded successfully]
[2024-09-09 23:12:47,524: INFO: common: created directory at: artifacts]
[2024-09-09 23:12:47,524: INFO: common: created directory at: artifacts/prepare_base_model]
[2024-09-09 23:12:47,734: WARNING: saving_api: You are saving your model as an HDF5 file via `model.save()` or `keras.saving.save_model(model)`. This file format is considered legacy. We recommend using instead the native Keras format, e.g. `model.save('my_model.keras')` or `keras.saving.save_model(model, 'my_model.keras')`. ]
[2024-09-09 23:12:47,808: WARNING: saving_api: You are saving your model as an HDF5 file via `model.save()` or `keras.saving.save_model(model)`. This file format is considered legacy. We recommend using instead the native Keras format, e.g. `model.save('my_model.keras')` or `keras.saving.save_model(model, 'my_model.keras')`. ]
[2024-09-09 23:12:47,864: INFO: main: >>>>>>>> stage Prepare base model completed <<<<<<

x===============x]
[2024-09-10 07:21:17,500: INFO: common: yaml file: config/config.yaml loaded successfully]
[2024-09-10 07:21:17,502: INFO: common: yaml file: params.yaml loaded successfully]
[2024-09-10 07:21:17,503: INFO: common: created directory at: artifacts]
[2024-09-10 21:14:49,345: INFO: main: >>>>>> stage Data Ingestion stage started <<<<<<<<<]
[2024-09-10 21:14:49,346: INFO: common: yaml file: config/config.yaml loaded successfully]
[2024-09-10 21:14:49,347: INFO: common: yaml file: params.yaml loaded successfully]
[2024-09-10 21:14:49,347: INFO: common: created directory at: artifacts]
[2024-09-10 21:14:49,347: INFO: common: created directory at: artifacts/data_ingestion]
[2024-09-10 21:14:49,348: INFO: data_ingestion: file already present of size: ~ 771248 KB]
[2024-09-10 21:14:53,836: INFO: main: >>>>>> stage Data Ingestion stage completed <<<<<<<<

x==============x]
[2024-09-10 21:14:53,836: INFO: main: ***************************]
[2024-09-10 21:14:53,836: INFO: main: >>>>>>>> stage Prepare base model started <<<<<<<<<<]
[2024-09-10 21:14:53,837: INFO: common: yaml file: config/config.yaml loaded successfully]
[2024-09-10 21:14:53,838: INFO: common: yaml file: params.yaml loaded successfully]
[2024-09-10 21:14:53,838: INFO: common: created directory at: artifacts]
[2024-09-10 21:14:53,838: INFO: common: created directory at: artifacts/prepare_base_model]
[2024-09-10 21:14:54,086: WARNING: saving_api: You are saving your model as an HDF5 file via `model.save()` or `keras.saving.save_model(model)`. This file format is considered legacy. We recommend using instead the native Keras format, e.g. `model.save('my_model.keras')` or `keras.saving.save_model(model, 'my_model.keras')`. ]
[2024-09-10 21:14:54,141: WARNING: saving_api: You are saving your model as an HDF5 file via `model.save()` or `keras.saving.save_model(model)`. This file format is considered legacy. We recommend using instead the native Keras format, e.g. `model.save('my_model.keras')` or `keras.saving.save_model(model, 'my_model.keras')`. ]
[2024-09-10 21:14:54,187: INFO: main: >>>>>>>> stage Prepare base model completed <<<<<<

x===============x]
[2024-09-10 21:16:13,227: INFO: common: yaml file: config/config.yaml loaded successfully]
[2024-09-10 21:16:13,229: INFO: common: yaml file: params.yaml loaded successfully]
[2024-09-10 21:16:13,230: INFO: common: created directory at: artifacts]
[2024-09-10 21:16:54,857: INFO: common: yaml file: config/config.yaml loaded successfully]
[2024-09-10 21:16:54,860: INFO: common: yaml file: params.yaml loaded successfully]
[2024-09-10 21:16:54,861: INFO: common: created directory at: artifacts]
[2024-09-10 21:34:53,977: INFO: common: yaml file: config/config.yaml loaded successfully]
[2024-09-10 21:34:53,980: INFO: common: yaml file: params.yaml loaded successfully]
[2024-09-10 21:34:53,980: INFO: common: created directory at: artifacts]
[2024-09-10 21:41:21,557: INFO: common: yaml file: config/config.yaml loaded successfully]
[2024-09-10 21:41:21,575: INFO: common: yaml file: params.yaml loaded successfully]
[2024-09-10 21:41:21,576: INFO: common: created directory at: artifacts]
[2024-09-10 21:41:21,577: INFO: common: created directory at: artifacts/prepare_callbacks/checkpoint_dir]
[2024-09-10 21:41:21,577: INFO: common: created directory at: artifacts/prepare_callbacks/tensorboard_log_dir]
[2024-09-10 21:42:05,410: INFO: common: yaml file: config/config.yaml loaded successfully]
[2024-09-10 21:42:05,413: INFO: common: yaml file: params.yaml loaded successfully]
[2024-09-10 21:42:05,414: INFO: common: created directory at: artifacts]
[2024-09-10 21:42:05,415: INFO: common: created directory at: artifacts/prepare_callbacks/checkpoint_dir]
[2024-09-10 21:42:05,416: INFO: common: created directory at: artifacts/prepare_callbacks/tensorboard_log_dir]
[2024-09-10 21:45:12,784: INFO: common: yaml file: config/config.yaml loaded successfully]
[2024-09-10 21:45:12,788: INFO: common: yaml file: params.yaml loaded successfully]
[2024-09-10 21:45:12,789: INFO: common: created directory at: artifacts]
[2024-09-10 21:45:12,790: INFO: common: created directory at: artifacts/prepare_callbacks/checkpoint_dir]
[2024-09-10 21:45:12,791: INFO: common: created directory at: artifacts/prepare_callbacks/tensorboard_log_dir]
[2024-09-12 07:39:41,403: INFO: common: yaml file: config/config.yaml loaded successfully]
[2024-09-12 07:39:41,406: INFO: common: yaml file: params.yaml loaded successfully]
[2024-09-12 07:39:41,407: INFO: common: created directory at: artifacts]
[2024-09-12 07:39:41,408: INFO: common: created directory at: artifacts/prepare_callbacks/checkpoint_dir]
[2024-09-12 07:39:41,408: INFO: common: created directory at: artifacts/prepare_callbacks/tensorboard_log_dir]
[2024-09-12 07:39:41,409: INFO: common: created directory at: artifacts/training]
[2024-09-12 07:39:41,551: WARNING: saving_utils: Compiled the loaded model, but the compiled metrics have yet to be built. `model.compile_metrics` will be empty until you train or evaluate the model.]
[2024-09-12 21:23:02,639: INFO: common: yaml file: config/config.yaml loaded successfully]
[2024-09-12 21:23:02,642: INFO: common: yaml file: params.yaml loaded successfully]
[2024-09-12 21:23:02,643: INFO: common: created directory at: artifacts]
[2024-09-12 21:23:02,644: INFO: common: created directory at: artifacts/prepare_callbacks/checkpoint_dir]
[2024-09-12 21:23:02,645: INFO: common: created directory at: artifacts/prepare_callbacks/tensorboard_log_dir]
[2024-09-12 21:23:02,646: INFO: common: created directory at: artifacts/training]
[2024-09-12 21:23:02,817: WARNING: saving_utils: Compiled the loaded model, but the compiled metrics have yet to be built. `model.compile_metrics` will be empty until you train or evaluate the model.]
[2024-09-13 07:16:23,230: INFO: common: yaml file: config/config.yaml loaded successfully]
[2024-09-13 07:16:23,233: INFO: common: yaml file: params.yaml loaded successfully]
[2024-09-13 07:16:23,235: INFO: common: created directory at: artifacts]
[2024-09-13 07:16:23,236: INFO: common: created directory at: artifacts/prepare_callbacks/checkpoint_dir]
[2024-09-13 07:16:23,236: INFO: common: created directory at: artifacts/prepare_callbacks/tensorboard_log_dir]
[2024-09-13 07:16:23,237: INFO: common: created directory at: artifacts/training]
[2024-09-13 07:16:23,362: WARNING: saving_utils: Compiled the loaded model, but the compiled metrics have yet to be built. `model.compile_metrics` will be empty until you train or evaluate the model.]
[2024-09-17 22:47:39,503: INFO: main: >>>>>> stage Data Ingestion stage started <<<<<<<<<]
[2024-09-17 22:47:39,505: INFO: common: yaml file: config/config.yaml loaded successfully]
[2024-09-17 22:47:39,506: INFO: common: yaml file: params.yaml loaded successfully]
[2024-09-17 22:47:39,506: INFO: common: created directory at: artifacts]
[2024-09-17 22:47:39,506: INFO: common: created directory at: artifacts/data_ingestion]
[2024-09-17 22:47:39,507: INFO: data_ingestion: file already present of size: ~ 771248 KB]
[2024-09-17 22:47:44,192: INFO: main: >>>>>> stage Data Ingestion stage completed <<<<<<<<

x==============x]
[2024-09-17 22:47:44,192: INFO: main: ***************************]
[2024-09-17 22:47:44,192: INFO: main: >>>>>>>> stage Prepare base model started <<<<<<<<<<]
[2024-09-17 22:47:44,193: INFO: common: yaml file: config/config.yaml loaded successfully]
[2024-09-17 22:47:44,194: INFO: common: yaml file: params.yaml loaded successfully]
[2024-09-17 22:47:44,194: INFO: common: created directory at: artifacts]
[2024-09-17 22:47:44,194: INFO: common: created directory at: artifacts/prepare_base_model]
[2024-09-17 22:47:44,445: WARNING: saving_api: You are saving your model as an HDF5 file via `model.save()` or `keras.saving.save_model(model)`. This file format is considered legacy. We recommend using instead the native Keras format, e.g. `model.save('my_model.keras')` or `keras.saving.save_model(model, 'my_model.keras')`. ]
[2024-09-17 22:47:44,522: WARNING: saving_api: You are saving your model as an HDF5 file via `model.save()` or `keras.saving.save_model(model)`. This file format is considered legacy. We recommend using instead the native Keras format, e.g. `model.save('my_model.keras')` or `keras.saving.save_model(model, 'my_model.keras')`. ]
[2024-09-17 22:47:44,575: INFO: main: >>>>>>>> stage Prepare base model completed <<<<<<

x===============x]
[2024-09-17 22:47:44,575: INFO: main: *****************************]
[2024-09-17 22:47:44,575: INFO: main: >>>>>>>>> stage Training started <<<<<<<<<<<<]
[2024-09-17 22:47:44,575: ERROR: main: name 'ModelTrainingPipeline' is not defined]
Traceback (most recent call last):
  File "/Users/krishnachaitanyaj/Practice/foodclassification/main.py", line 33, in <module>
    obj = ModelTrainingPipeline()
          ^^^^^^^^^^^^^^^^^^^^^
NameError: name 'ModelTrainingPipeline' is not defined
[2024-09-17 22:54:16,775: INFO: main: >>>>>> stage Data Ingestion stage started <<<<<<<<<]
[2024-09-17 22:54:16,777: INFO: common: yaml file: config/config.yaml loaded successfully]
[2024-09-17 22:54:16,777: INFO: common: yaml file: params.yaml loaded successfully]
[2024-09-17 22:54:16,778: INFO: common: created directory at: artifacts]
[2024-09-17 22:54:16,778: INFO: common: created directory at: artifacts/data_ingestion]
[2024-09-17 22:54:16,778: INFO: data_ingestion: file already present of size: ~ 771248 KB]
[2024-09-17 22:54:21,001: INFO: main: >>>>>> stage Data Ingestion stage completed <<<<<<<<

x==============x]
[2024-09-17 22:54:21,001: INFO: main: ***************************]
[2024-09-17 22:54:21,001: INFO: main: >>>>>>>> stage Prepare base model started <<<<<<<<<<]
[2024-09-17 22:54:21,003: INFO: common: yaml file: config/config.yaml loaded successfully]
[2024-09-17 22:54:21,003: INFO: common: yaml file: params.yaml loaded successfully]
[2024-09-17 22:54:21,003: INFO: common: created directory at: artifacts]
[2024-09-17 22:54:21,003: INFO: common: created directory at: artifacts/prepare_base_model]
[2024-09-17 22:54:21,203: WARNING: saving_api: You are saving your model as an HDF5 file via `model.save()` or `keras.saving.save_model(model)`. This file format is considered legacy. We recommend using instead the native Keras format, e.g. `model.save('my_model.keras')` or `keras.saving.save_model(model, 'my_model.keras')`. ]
[2024-09-17 22:54:21,258: WARNING: saving_api: You are saving your model as an HDF5 file via `model.save()` or `keras.saving.save_model(model)`. This file format is considered legacy. We recommend using instead the native Keras format, e.g. `model.save('my_model.keras')` or `keras.saving.save_model(model, 'my_model.keras')`. ]
[2024-09-17 22:54:21,291: INFO: main: >>>>>>>> stage Prepare base model completed <<<<<<

x===============x]
[2024-09-17 22:54:21,291: INFO: main: *****************************]
[2024-09-17 22:54:21,291: INFO: main: >>>>>>>>> stage Training started <<<<<<<<<<<<]
[2024-09-17 22:54:21,292: INFO: common: yaml file: config/config.yaml loaded successfully]
[2024-09-17 22:54:21,293: INFO: common: yaml file: params.yaml loaded successfully]
[2024-09-17 22:54:21,293: INFO: common: created directory at: artifacts]
[2024-09-17 22:54:21,297: INFO: common: created directory at: artifacts/training]
[2024-09-17 22:54:21,297: ERROR: main: 'ConfigurationManager' object has no attribute 'train_img_csv']
Traceback (most recent call last):
  File "/Users/krishnachaitanyaj/Practice/foodclassification/main.py", line 35, in <module>
    obj.main()
  File "/Users/krishnachaitanyaj/Practice/foodclassification/src/foodclassification/pipeline/stage_03_training.py", line 14, in main
    training_config = config.get_training_config()
                      ^^^^^^^^^^^^^^^^^^^^^^^^^^^^
  File "/Users/krishnachaitanyaj/Practice/foodclassification/src/foodclassification/config/configuration.py", line 86, in get_training_config
    train_img_csv=self.train_img_csv,
                  ^^^^^^^^^^^^^^^^^^
AttributeError: 'ConfigurationManager' object has no attribute 'train_img_csv'
[2024-09-17 22:58:40,486: INFO: main: >>>>>> stage Data Ingestion stage started <<<<<<<<<]
[2024-09-17 22:58:40,487: INFO: common: yaml file: config/config.yaml loaded successfully]
[2024-09-17 22:58:40,487: INFO: common: yaml file: params.yaml loaded successfully]
[2024-09-17 22:58:40,488: INFO: common: created directory at: artifacts]
[2024-09-17 22:58:40,488: INFO: common: created directory at: artifacts/data_ingestion]
[2024-09-17 22:58:40,488: INFO: data_ingestion: file already present of size: ~ 771248 KB]
[2024-09-17 22:58:44,573: INFO: main: >>>>>> stage Data Ingestion stage completed <<<<<<<<

x==============x]
[2024-09-17 22:58:44,573: INFO: main: ***************************]
[2024-09-17 22:58:44,573: INFO: main: >>>>>>>> stage Prepare base model started <<<<<<<<<<]
[2024-09-17 22:58:44,574: INFO: common: yaml file: config/config.yaml loaded successfully]
[2024-09-17 22:58:44,575: INFO: common: yaml file: params.yaml loaded successfully]
[2024-09-17 22:58:44,575: INFO: common: created directory at: artifacts]
[2024-09-17 22:58:44,575: INFO: common: created directory at: artifacts/prepare_base_model]
[2024-09-17 22:58:44,781: WARNING: saving_api: You are saving your model as an HDF5 file via `model.save()` or `keras.saving.save_model(model)`. This file format is considered legacy. We recommend using instead the native Keras format, e.g. `model.save('my_model.keras')` or `keras.saving.save_model(model, 'my_model.keras')`. ]
[2024-09-17 22:58:44,841: WARNING: saving_api: You are saving your model as an HDF5 file via `model.save()` or `keras.saving.save_model(model)`. This file format is considered legacy. We recommend using instead the native Keras format, e.g. `model.save('my_model.keras')` or `keras.saving.save_model(model, 'my_model.keras')`. ]
[2024-09-17 22:58:44,881: INFO: main: >>>>>>>> stage Prepare base model completed <<<<<<

x===============x]
[2024-09-17 22:58:44,881: INFO: main: *****************************]
[2024-09-17 22:58:44,881: INFO: main: >>>>>>>>> stage Training started <<<<<<<<<<<<]
[2024-09-17 22:58:44,882: INFO: common: yaml file: config/config.yaml loaded successfully]
[2024-09-17 22:58:44,882: INFO: common: yaml file: params.yaml loaded successfully]
[2024-09-17 22:58:44,883: INFO: common: created directory at: artifacts]
[2024-09-17 22:58:44,883: INFO: common: created directory at: artifacts/training]
[2024-09-17 22:58:44,883: ERROR: main: 'ConfigurationManager' object has no attribute 'train_img_csv']
Traceback (most recent call last):
  File "/Users/krishnachaitanyaj/Practice/foodclassification/main.py", line 35, in <module>
    obj.main()
  File "/Users/krishnachaitanyaj/Practice/foodclassification/src/foodclassification/pipeline/stage_03_training.py", line 14, in main
    training_config = config.get_training_config()
                      ^^^^^^^^^^^^^^^^^^^^^^^^^^^^
  File "/Users/krishnachaitanyaj/Practice/foodclassification/src/foodclassification/config/configuration.py", line 86, in get_training_config
    train_img_csv=Path(self.train_img_csv),
                       ^^^^^^^^^^^^^^^^^^
AttributeError: 'ConfigurationManager' object has no attribute 'train_img_csv'
[2024-09-17 23:03:52,379: INFO: main: >>>>>> stage Data Ingestion stage started <<<<<<<<<]
[2024-09-17 23:03:52,380: INFO: common: yaml file: config/config.yaml loaded successfully]
[2024-09-17 23:03:52,381: INFO: common: yaml file: params.yaml loaded successfully]
[2024-09-17 23:03:52,381: INFO: common: created directory at: artifacts]
[2024-09-17 23:03:52,381: INFO: common: created directory at: artifacts/data_ingestion]
[2024-09-17 23:03:52,381: INFO: data_ingestion: file already present of size: ~ 771248 KB]
[2024-09-17 23:03:56,431: INFO: main: >>>>>> stage Data Ingestion stage completed <<<<<<<<

x==============x]
[2024-09-17 23:03:56,432: INFO: main: ***************************]
[2024-09-17 23:03:56,432: INFO: main: >>>>>>>> stage Prepare base model started <<<<<<<<<<]
[2024-09-17 23:03:56,432: INFO: common: yaml file: config/config.yaml loaded successfully]
[2024-09-17 23:03:56,433: INFO: common: yaml file: params.yaml loaded successfully]
[2024-09-17 23:03:56,433: INFO: common: created directory at: artifacts]
[2024-09-17 23:03:56,433: INFO: common: created directory at: artifacts/prepare_base_model]
[2024-09-17 23:03:56,648: WARNING: saving_api: You are saving your model as an HDF5 file via `model.save()` or `keras.saving.save_model(model)`. This file format is considered legacy. We recommend using instead the native Keras format, e.g. `model.save('my_model.keras')` or `keras.saving.save_model(model, 'my_model.keras')`. ]
[2024-09-17 23:03:56,766: WARNING: saving_api: You are saving your model as an HDF5 file via `model.save()` or `keras.saving.save_model(model)`. This file format is considered legacy. We recommend using instead the native Keras format, e.g. `model.save('my_model.keras')` or `keras.saving.save_model(model, 'my_model.keras')`. ]
[2024-09-17 23:03:56,803: INFO: main: >>>>>>>> stage Prepare base model completed <<<<<<

x===============x]
[2024-09-17 23:03:56,803: INFO: main: *****************************]
[2024-09-17 23:03:56,803: INFO: main: >>>>>>>>> stage Training started <<<<<<<<<<<<]
[2024-09-17 23:03:56,804: INFO: common: yaml file: config/config.yaml loaded successfully]
[2024-09-17 23:03:56,805: INFO: common: yaml file: params.yaml loaded successfully]
[2024-09-17 23:03:56,805: INFO: common: created directory at: artifacts]
[2024-09-17 23:03:56,805: INFO: common: created directory at: artifacts/training]
[2024-09-17 23:03:56,805: ERROR: main: TrainingConfig.__init__() got an unexpected keyword argument 'train_img_csv']
Traceback (most recent call last):
  File "/Users/krishnachaitanyaj/Practice/foodclassification/main.py", line 35, in <module>
    obj.main()
  File "/Users/krishnachaitanyaj/Practice/foodclassification/src/foodclassification/pipeline/stage_03_training.py", line 14, in main
    training_config = config.get_training_config()
                      ^^^^^^^^^^^^^^^^^^^^^^^^^^^^
  File "/Users/krishnachaitanyaj/Practice/foodclassification/src/foodclassification/config/configuration.py", line 81, in get_training_config
    training_config = TrainingConfig(
                      ^^^^^^^^^^^^^^^
TypeError: TrainingConfig.__init__() got an unexpected keyword argument 'train_img_csv'
[2024-09-17 23:10:16,509: INFO: main: >>>>>> stage Data Ingestion stage started <<<<<<<<<]
[2024-09-17 23:10:16,510: INFO: common: yaml file: config/config.yaml loaded successfully]
[2024-09-17 23:10:16,511: INFO: common: yaml file: params.yaml loaded successfully]
[2024-09-17 23:10:16,511: INFO: common: created directory at: artifacts]
[2024-09-17 23:10:16,511: INFO: common: created directory at: artifacts/data_ingestion]
[2024-09-17 23:10:16,511: INFO: data_ingestion: file already present of size: ~ 771248 KB]
[2024-09-17 23:10:20,599: INFO: main: >>>>>> stage Data Ingestion stage completed <<<<<<<<

x==============x]
[2024-09-17 23:10:20,599: INFO: main: ***************************]
[2024-09-17 23:10:20,599: INFO: main: >>>>>>>> stage Prepare base model started <<<<<<<<<<]
[2024-09-17 23:10:20,600: INFO: common: yaml file: config/config.yaml loaded successfully]
[2024-09-17 23:10:20,600: INFO: common: yaml file: params.yaml loaded successfully]
[2024-09-17 23:10:20,600: INFO: common: created directory at: artifacts]
[2024-09-17 23:10:20,600: INFO: common: created directory at: artifacts/prepare_base_model]
[2024-09-17 23:10:20,820: WARNING: saving_api: You are saving your model as an HDF5 file via `model.save()` or `keras.saving.save_model(model)`. This file format is considered legacy. We recommend using instead the native Keras format, e.g. `model.save('my_model.keras')` or `keras.saving.save_model(model, 'my_model.keras')`. ]
[2024-09-17 23:10:20,875: WARNING: saving_api: You are saving your model as an HDF5 file via `model.save()` or `keras.saving.save_model(model)`. This file format is considered legacy. We recommend using instead the native Keras format, e.g. `model.save('my_model.keras')` or `keras.saving.save_model(model, 'my_model.keras')`. ]
[2024-09-17 23:10:20,931: INFO: main: >>>>>>>> stage Prepare base model completed <<<<<<

x===============x]
[2024-09-17 23:10:20,931: INFO: main: *****************************]
[2024-09-17 23:10:20,931: INFO: main: >>>>>>>>> stage Training started <<<<<<<<<<<<]
[2024-09-17 23:10:20,933: INFO: common: yaml file: config/config.yaml loaded successfully]
[2024-09-17 23:10:20,933: INFO: common: yaml file: params.yaml loaded successfully]
[2024-09-17 23:10:20,933: INFO: common: created directory at: artifacts]
[2024-09-17 23:10:20,933: INFO: common: created directory at: artifacts/training]
[2024-09-17 23:10:20,933: ERROR: main: TrainingConfig.__init__() got an unexpected keyword argument 'train_img_csv']
Traceback (most recent call last):
  File "/Users/krishnachaitanyaj/Practice/foodclassification/main.py", line 35, in <module>
    obj.main()
  File "/Users/krishnachaitanyaj/Practice/foodclassification/src/foodclassification/pipeline/stage_03_training.py", line 14, in main
    training_config = config.get_training_config()
                      ^^^^^^^^^^^^^^^^^^^^^^^^^^^^
  File "/Users/krishnachaitanyaj/Practice/foodclassification/src/foodclassification/config/configuration.py", line 81, in get_training_config
    training_config = TrainingConfig(
                      ^^^^^^^^^^^^^^^
TypeError: TrainingConfig.__init__() got an unexpected keyword argument 'train_img_csv'
[2024-09-17 23:12:32,331: INFO: main: >>>>>> stage Data Ingestion stage started <<<<<<<<<]
[2024-09-17 23:12:32,332: INFO: common: yaml file: config/config.yaml loaded successfully]
[2024-09-17 23:12:32,332: INFO: common: yaml file: params.yaml loaded successfully]
[2024-09-17 23:12:32,333: INFO: common: created directory at: artifacts]
[2024-09-17 23:12:32,333: INFO: common: created directory at: artifacts/data_ingestion]
[2024-09-17 23:12:32,333: INFO: data_ingestion: file already present of size: ~ 771248 KB]
[2024-09-17 23:12:36,417: INFO: main: >>>>>> stage Data Ingestion stage completed <<<<<<<<

x==============x]
[2024-09-17 23:12:36,417: INFO: main: ***************************]
[2024-09-17 23:12:36,417: INFO: main: >>>>>>>> stage Prepare base model started <<<<<<<<<<]
[2024-09-17 23:12:36,418: INFO: common: yaml file: config/config.yaml loaded successfully]
[2024-09-17 23:12:36,418: INFO: common: yaml file: params.yaml loaded successfully]
[2024-09-17 23:12:36,418: INFO: common: created directory at: artifacts]
[2024-09-17 23:12:36,418: INFO: common: created directory at: artifacts/prepare_base_model]
[2024-09-17 23:12:36,621: WARNING: saving_api: You are saving your model as an HDF5 file via `model.save()` or `keras.saving.save_model(model)`. This file format is considered legacy. We recommend using instead the native Keras format, e.g. `model.save('my_model.keras')` or `keras.saving.save_model(model, 'my_model.keras')`. ]
[2024-09-17 23:12:36,736: WARNING: saving_api: You are saving your model as an HDF5 file via `model.save()` or `keras.saving.save_model(model)`. This file format is considered legacy. We recommend using instead the native Keras format, e.g. `model.save('my_model.keras')` or `keras.saving.save_model(model, 'my_model.keras')`. ]
[2024-09-17 23:12:36,771: INFO: main: >>>>>>>> stage Prepare base model completed <<<<<<

x===============x]
[2024-09-17 23:12:36,771: INFO: main: *****************************]
[2024-09-17 23:12:36,771: INFO: main: >>>>>>>>> stage Training started <<<<<<<<<<<<]
[2024-09-17 23:12:36,772: INFO: common: yaml file: config/config.yaml loaded successfully]
[2024-09-17 23:12:36,773: INFO: common: yaml file: params.yaml loaded successfully]
[2024-09-17 23:12:36,773: INFO: common: created directory at: artifacts]
[2024-09-17 23:12:36,773: INFO: common: created directory at: artifacts/training]
[2024-09-17 23:12:36,773: ERROR: main: TrainingConfig.__init__() got an unexpected keyword argument 'train_img_csv']
Traceback (most recent call last):
  File "/Users/krishnachaitanyaj/Practice/foodclassification/main.py", line 35, in <module>
    obj.main()
  File "/Users/krishnachaitanyaj/Practice/foodclassification/src/foodclassification/pipeline/stage_03_training.py", line 14, in main
    training_config = config.get_training_config()
                      ^^^^^^^^^^^^^^^^^^^^^^^^^^^^
  File "/Users/krishnachaitanyaj/Practice/foodclassification/src/foodclassification/config/configuration.py", line 81, in get_training_config
    training_config = TrainingConfig(
                      ^^^^^^^^^^^^^^^
TypeError: TrainingConfig.__init__() got an unexpected keyword argument 'train_img_csv'
[2024-09-17 23:17:15,209: INFO: main: >>>>>> stage Data Ingestion stage started <<<<<<<<<]
[2024-09-17 23:17:15,210: INFO: common: yaml file: config/config.yaml loaded successfully]
[2024-09-17 23:17:15,211: INFO: common: yaml file: params.yaml loaded successfully]
[2024-09-17 23:17:15,211: INFO: common: created directory at: artifacts]
[2024-09-17 23:17:15,211: INFO: common: created directory at: artifacts/data_ingestion]
[2024-09-17 23:17:15,211: INFO: data_ingestion: file already present of size: ~ 771248 KB]
[2024-09-17 23:17:19,326: INFO: main: >>>>>> stage Data Ingestion stage completed <<<<<<<<

x==============x]
[2024-09-17 23:17:19,326: INFO: main: ***************************]
[2024-09-17 23:17:19,326: INFO: main: >>>>>>>> stage Prepare base model started <<<<<<<<<<]
[2024-09-17 23:17:19,327: INFO: common: yaml file: config/config.yaml loaded successfully]
[2024-09-17 23:17:19,328: INFO: common: yaml file: params.yaml loaded successfully]
[2024-09-17 23:17:19,328: INFO: common: created directory at: artifacts]
[2024-09-17 23:17:19,328: INFO: common: created directory at: artifacts/prepare_base_model]
[2024-09-17 23:17:19,532: WARNING: saving_api: You are saving your model as an HDF5 file via `model.save()` or `keras.saving.save_model(model)`. This file format is considered legacy. We recommend using instead the native Keras format, e.g. `model.save('my_model.keras')` or `keras.saving.save_model(model, 'my_model.keras')`. ]
[2024-09-17 23:17:19,607: WARNING: saving_api: You are saving your model as an HDF5 file via `model.save()` or `keras.saving.save_model(model)`. This file format is considered legacy. We recommend using instead the native Keras format, e.g. `model.save('my_model.keras')` or `keras.saving.save_model(model, 'my_model.keras')`. ]
[2024-09-17 23:17:19,640: INFO: main: >>>>>>>> stage Prepare base model completed <<<<<<

x===============x]
[2024-09-17 23:17:19,641: INFO: main: *****************************]
[2024-09-17 23:17:19,641: INFO: main: >>>>>>>>> stage Training started <<<<<<<<<<<<]
[2024-09-17 23:17:19,642: INFO: common: yaml file: config/config.yaml loaded successfully]
[2024-09-17 23:17:19,642: INFO: common: yaml file: params.yaml loaded successfully]
[2024-09-17 23:17:19,642: INFO: common: created directory at: artifacts]
[2024-09-17 23:17:19,642: INFO: common: created directory at: artifacts/training]
[2024-09-17 23:17:19,642: ERROR: main: TrainingConfig.__init__() got an unexpected keyword argument 'train_img_csv']
Traceback (most recent call last):
  File "/Users/krishnachaitanyaj/Practice/foodclassification/main.py", line 35, in <module>
    obj.main()
  File "/Users/krishnachaitanyaj/Practice/foodclassification/src/foodclassification/pipeline/stage_03_training.py", line 14, in main
    training_config = config.get_training_config()
                      ^^^^^^^^^^^^^^^^^^^^^^^^^^^^
  File "/Users/krishnachaitanyaj/Practice/foodclassification/src/foodclassification/config/configuration.py", line 81, in get_training_config
    training_config = TrainingConfig(
                      ^^^^^^^^^^^^^^^
TypeError: TrainingConfig.__init__() got an unexpected keyword argument 'train_img_csv'
[2024-09-19 20:58:14,993: INFO: main: >>>>>> stage Data Ingestion stage started <<<<<<<<<]
[2024-09-19 20:58:14,995: INFO: common: yaml file: config/config.yaml loaded successfully]
[2024-09-19 20:58:14,996: INFO: common: yaml file: params.yaml loaded successfully]
[2024-09-19 20:58:14,996: INFO: common: created directory at: artifacts]
[2024-09-19 20:58:14,996: INFO: common: created directory at: artifacts/data_ingestion]
[2024-09-19 20:58:14,996: INFO: data_ingestion: file already present of size: ~ 771248 KB]
[2024-09-19 20:58:19,539: INFO: main: >>>>>> stage Data Ingestion stage completed <<<<<<<<

x==============x]
[2024-09-19 20:58:19,540: INFO: main: ***************************]
[2024-09-19 20:58:19,540: INFO: main: >>>>>>>> stage Prepare base model started <<<<<<<<<<]
[2024-09-19 20:58:19,541: INFO: common: yaml file: config/config.yaml loaded successfully]
[2024-09-19 20:58:19,542: INFO: common: yaml file: params.yaml loaded successfully]
[2024-09-19 20:58:19,542: INFO: common: created directory at: artifacts]
[2024-09-19 20:58:19,542: INFO: common: created directory at: artifacts/prepare_base_model]
[2024-09-19 20:58:19,756: WARNING: saving_api: You are saving your model as an HDF5 file via `model.save()` or `keras.saving.save_model(model)`. This file format is considered legacy. We recommend using instead the native Keras format, e.g. `model.save('my_model.keras')` or `keras.saving.save_model(model, 'my_model.keras')`. ]
[2024-09-19 20:58:19,885: WARNING: saving_api: You are saving your model as an HDF5 file via `model.save()` or `keras.saving.save_model(model)`. This file format is considered legacy. We recommend using instead the native Keras format, e.g. `model.save('my_model.keras')` or `keras.saving.save_model(model, 'my_model.keras')`. ]
[2024-09-19 20:58:19,918: INFO: main: >>>>>>>> stage Prepare base model completed <<<<<<

x===============x]
[2024-09-19 20:58:19,918: INFO: main: *****************************]
[2024-09-19 20:58:19,918: INFO: main: >>>>>>>>> stage Training started <<<<<<<<<<<<]
[2024-09-19 20:58:19,919: INFO: common: yaml file: config/config.yaml loaded successfully]
[2024-09-19 20:58:19,920: INFO: common: yaml file: params.yaml loaded successfully]
[2024-09-19 20:58:19,920: INFO: common: created directory at: artifacts]
[2024-09-19 20:58:19,920: INFO: common: created directory at: artifacts/training]
[2024-09-19 21:11:38,674: ERROR: main: 'PlotLosses' object has no attribute 'losses']
Traceback (most recent call last):
  File "/Users/krishnachaitanyaj/Practice/foodclassification/main.py", line 35, in <module>
    obj.main()
  File "/Users/krishnachaitanyaj/Practice/foodclassification/src/foodclassification/pipeline/stage_03_training.py", line 16, in main
    training.train()
  File "/Users/krishnachaitanyaj/Practice/foodclassification/src/foodclassification/components/training.py", line 80, in train
    history = model.fit(x=self.batch_generator(batch_size, self.generate_data(X_dev, train_path, y_dev)), epochs=num_epoch,
              ^^^^^^^^^^^^^^^^^^^^^^^^^^^^^^^^^^^^^^^^^^^^^^^^^^^^^^^^^^^^^^^^^^^^^^^^^^^^^^^^^^^^^^^^^^^^^^^^^^^^^^^^^^^^^
  File "/Users/krishnachaitanyaj/Practice/foodclassification/.venv/lib/python3.11/site-packages/keras/src/utils/traceback_utils.py", line 122, in error_handler
    raise e.with_traceback(filtered_tb) from None
  File "/Users/krishnachaitanyaj/Practice/foodclassification/src/foodclassification/components/training.py", line 20, in on_epoch_end
    self.losses.append(logs.get('loss'))
    ^^^^^^^^^^^
AttributeError: 'PlotLosses' object has no attribute 'losses'
[2024-09-19 21:16:31,288: INFO: main: >>>>>> stage Data Ingestion stage started <<<<<<<<<]
[2024-09-19 21:16:31,289: INFO: common: yaml file: config/config.yaml loaded successfully]
[2024-09-19 21:16:31,290: INFO: common: yaml file: params.yaml loaded successfully]
[2024-09-19 21:16:31,290: INFO: common: created directory at: artifacts]
[2024-09-19 21:16:31,290: INFO: common: created directory at: artifacts/data_ingestion]
[2024-09-19 21:16:31,290: INFO: data_ingestion: file already present of size: ~ 771248 KB]
[2024-09-19 21:16:35,567: INFO: main: >>>>>> stage Data Ingestion stage completed <<<<<<<<

x==============x]
[2024-09-19 21:16:35,567: INFO: main: ***************************]
[2024-09-19 21:16:35,567: INFO: main: >>>>>>>> stage Prepare base model started <<<<<<<<<<]
[2024-09-19 21:16:35,568: INFO: common: yaml file: config/config.yaml loaded successfully]
[2024-09-19 21:16:35,568: INFO: common: yaml file: params.yaml loaded successfully]
[2024-09-19 21:16:35,568: INFO: common: created directory at: artifacts]
[2024-09-19 21:16:35,568: INFO: common: created directory at: artifacts/prepare_base_model]
[2024-09-19 21:16:35,758: WARNING: saving_api: You are saving your model as an HDF5 file via `model.save()` or `keras.saving.save_model(model)`. This file format is considered legacy. We recommend using instead the native Keras format, e.g. `model.save('my_model.keras')` or `keras.saving.save_model(model, 'my_model.keras')`. ]
[2024-09-19 21:16:35,803: WARNING: saving_api: You are saving your model as an HDF5 file via `model.save()` or `keras.saving.save_model(model)`. This file format is considered legacy. We recommend using instead the native Keras format, e.g. `model.save('my_model.keras')` or `keras.saving.save_model(model, 'my_model.keras')`. ]
[2024-09-19 21:16:35,841: INFO: main: >>>>>>>> stage Prepare base model completed <<<<<<

x===============x]
[2024-09-19 21:16:35,841: INFO: main: *****************************]
[2024-09-19 21:16:35,841: INFO: main: >>>>>>>>> stage Training started <<<<<<<<<<<<]
[2024-09-19 21:16:35,842: INFO: common: yaml file: config/config.yaml loaded successfully]
[2024-09-19 21:16:35,842: INFO: common: yaml file: params.yaml loaded successfully]
[2024-09-19 21:16:35,843: INFO: common: created directory at: artifacts]
[2024-09-19 21:16:35,843: INFO: common: created directory at: artifacts/training]
[2024-09-19 21:30:47,412: ERROR: main: 'History' object has no attribute 'save']
Traceback (most recent call last):
  File "/Users/krishnachaitanyaj/Practice/foodclassification/main.py", line 35, in <module>
    obj.main()
  File "/Users/krishnachaitanyaj/Practice/foodclassification/src/foodclassification/pipeline/stage_03_training.py", line 16, in main
    training.train()
  File "/Users/krishnachaitanyaj/Practice/foodclassification/src/foodclassification/components/training.py", line 84, in train
    self.save_model(path=self.config.trained_model_path, model=history)
  File "/Users/krishnachaitanyaj/Practice/foodclassification/src/foodclassification/components/training.py", line 66, in save_model
    model.save(path)
    ^^^^^^^^^^
AttributeError: 'History' object has no attribute 'save'
[2024-09-19 21:54:05,963: INFO: main: >>>>>> stage Data Ingestion stage started <<<<<<<<<]
[2024-09-19 21:54:05,964: INFO: common: yaml file: config/config.yaml loaded successfully]
[2024-09-19 21:54:05,965: INFO: common: yaml file: params.yaml loaded successfully]
[2024-09-19 21:54:05,965: INFO: common: created directory at: artifacts]
[2024-09-19 21:54:05,965: INFO: common: created directory at: artifacts/data_ingestion]
[2024-09-19 21:54:05,965: INFO: data_ingestion: file already present of size: ~ 771248 KB]
[2024-09-19 21:54:10,422: INFO: main: >>>>>> stage Data Ingestion stage completed <<<<<<<<

x==============x]
[2024-09-19 21:54:10,423: INFO: main: ***************************]
[2024-09-19 21:54:10,423: INFO: main: >>>>>>>> stage Prepare base model started <<<<<<<<<<]
[2024-09-19 21:54:10,424: INFO: common: yaml file: config/config.yaml loaded successfully]
[2024-09-19 21:54:10,424: INFO: common: yaml file: params.yaml loaded successfully]
[2024-09-19 21:54:10,425: INFO: common: created directory at: artifacts]
[2024-09-19 21:54:10,425: INFO: common: created directory at: artifacts/prepare_base_model]
[2024-09-19 21:54:10,620: WARNING: saving_api: You are saving your model as an HDF5 file via `model.save()` or `keras.saving.save_model(model)`. This file format is considered legacy. We recommend using instead the native Keras format, e.g. `model.save('my_model.keras')` or `keras.saving.save_model(model, 'my_model.keras')`. ]
[2024-09-19 21:54:10,682: WARNING: saving_api: You are saving your model as an HDF5 file via `model.save()` or `keras.saving.save_model(model)`. This file format is considered legacy. We recommend using instead the native Keras format, e.g. `model.save('my_model.keras')` or `keras.saving.save_model(model, 'my_model.keras')`. ]
[2024-09-19 21:54:10,715: INFO: main: >>>>>>>> stage Prepare base model completed <<<<<<

x===============x]
[2024-09-19 21:54:10,715: INFO: main: *****************************]
[2024-09-19 21:54:10,715: INFO: main: >>>>>>>>> stage Training started <<<<<<<<<<<<]
[2024-09-19 21:54:10,716: INFO: common: yaml file: config/config.yaml loaded successfully]
[2024-09-19 21:54:10,717: INFO: common: yaml file: params.yaml loaded successfully]
[2024-09-19 21:54:10,717: INFO: common: created directory at: artifacts]
[2024-09-19 21:54:10,717: INFO: common: created directory at: artifacts/training]
[2024-09-19 22:06:43,802: WARNING: saving_api: You are saving your model as an HDF5 file via `model.save()` or `keras.saving.save_model(model)`. This file format is considered legacy. We recommend using instead the native Keras format, e.g. `model.save('my_model.keras')` or `keras.saving.save_model(model, 'my_model.keras')`. ]
[2024-09-19 22:06:44,041: INFO: main: >>>>>>>>>>> stage Training completed <<<<<<<<<<<

x===============x]
