[2024-09-02 08:52:12,706: INFO: main: This is use to test logging messages]
[2024-09-07 18:31:30,460: INFO: main: >>>>>> stage Data Ingestion stage started <<<<<<<<<]
[2024-09-07 18:31:30,461: ERROR: main: name 'BoxValueError' is not defined]
Traceback (most recent call last):
  File "/Users/kjaggav1/Library/CloudStorage/OneDrive-JCPenney/myworkspace/practice/foodclassification/src/foodclassification/utils/common.py", line 17, in read_yaml
    content = yaml.safe_load(yaml_file)
              ^^^^
NameError: name 'yaml' is not defined

During handling of the above exception, another exception occurred:

Traceback (most recent call last):
  File "/Users/kjaggav1/Library/CloudStorage/OneDrive-JCPenney/myworkspace/practice/foodclassification/main.py", line 11, in <module>
    obj.main()
  File "/Users/kjaggav1/Library/CloudStorage/OneDrive-JCPenney/myworkspace/practice/foodclassification/src/foodclassification/pipeline/stage_01_data_ingestion.py", line 12, in main
    config = ConfigurationManager()
             ^^^^^^^^^^^^^^^^^^^^^^
  File "/Users/kjaggav1/Library/CloudStorage/OneDrive-JCPenney/myworkspace/practice/foodclassification/src/foodclassification/config/configuration.py", line 11, in __init__
    self.config = read_yaml(config_filepath)
                  ^^^^^^^^^^^^^^^^^^^^^^^^^^
  File "/Users/kjaggav1/Library/CloudStorage/OneDrive-JCPenney/myworkspace/practice/foodclassification/.venv/lib/python3.12/site-packages/ensure/main.py", line 872, in __call__
    return_val = self.f(*args, **kwargs)
                 ^^^^^^^^^^^^^^^^^^^^^^^
  File "/Users/kjaggav1/Library/CloudStorage/OneDrive-JCPenney/myworkspace/practice/foodclassification/src/foodclassification/utils/common.py", line 20, in read_yaml
    except BoxValueError:
           ^^^^^^^^^^^^^
NameError: name 'BoxValueError' is not defined. Did you mean: 'ValueError'?
[2024-09-07 18:31:55,163: INFO: main: >>>>>> stage Data Ingestion stage started <<<<<<<<<]
[2024-09-07 18:31:55,163: ERROR: main: name 'BoxValueError' is not defined]
Traceback (most recent call last):
  File "/Users/kjaggav1/Library/CloudStorage/OneDrive-JCPenney/myworkspace/practice/foodclassification/src/foodclassification/utils/common.py", line 17, in read_yaml
    content = yaml.safe_load(yaml_file)
              ^^^^
NameError: name 'yaml' is not defined

During handling of the above exception, another exception occurred:

Traceback (most recent call last):
  File "/Users/kjaggav1/Library/CloudStorage/OneDrive-JCPenney/myworkspace/practice/foodclassification/main.py", line 11, in <module>
    obj.main()
  File "/Users/kjaggav1/Library/CloudStorage/OneDrive-JCPenney/myworkspace/practice/foodclassification/src/foodclassification/pipeline/stage_01_data_ingestion.py", line 12, in main
    config = ConfigurationManager()
             ^^^^^^^^^^^^^^^^^^^^^^
  File "/Users/kjaggav1/Library/CloudStorage/OneDrive-JCPenney/myworkspace/practice/foodclassification/src/foodclassification/config/configuration.py", line 11, in __init__
    self.config = read_yaml(config_filepath)
                  ^^^^^^^^^^^^^^^^^^^^^^^^^^
  File "/Users/kjaggav1/Library/CloudStorage/OneDrive-JCPenney/myworkspace/practice/foodclassification/.venv/lib/python3.12/site-packages/ensure/main.py", line 872, in __call__
    return_val = self.f(*args, **kwargs)
                 ^^^^^^^^^^^^^^^^^^^^^^^
  File "/Users/kjaggav1/Library/CloudStorage/OneDrive-JCPenney/myworkspace/practice/foodclassification/src/foodclassification/utils/common.py", line 20, in read_yaml
    except BoxValueError:
           ^^^^^^^^^^^^^
NameError: name 'BoxValueError' is not defined. Did you mean: 'ValueError'?
[2024-09-07 18:35:33,311: INFO: main: >>>>>> stage Data Ingestion stage started <<<<<<<<<]
[2024-09-07 18:35:33,311: ERROR: main: name 'BoxValueError' is not defined]
Traceback (most recent call last):
  File "/Users/kjaggav1/Library/CloudStorage/OneDrive-JCPenney/myworkspace/practice/foodclassification/src/foodclassification/utils/common.py", line 17, in read_yaml
    content = yaml.safe_load(yaml_file)
              ^^^^
NameError: name 'yaml' is not defined

During handling of the above exception, another exception occurred:

Traceback (most recent call last):
  File "/Users/kjaggav1/Library/CloudStorage/OneDrive-JCPenney/myworkspace/practice/foodclassification/main.py", line 11, in <module>
    obj.main()
  File "/Users/kjaggav1/Library/CloudStorage/OneDrive-JCPenney/myworkspace/practice/foodclassification/src/foodclassification/pipeline/stage_01_data_ingestion.py", line 12, in main
    config = ConfigurationManager()
             ^^^^^^^^^^^^^^^^^^^^^^
  File "/Users/kjaggav1/Library/CloudStorage/OneDrive-JCPenney/myworkspace/practice/foodclassification/src/foodclassification/config/configuration.py", line 11, in __init__
    self.config = read_yaml(config_filepath)
                  ^^^^^^^^^^^^^^^^^^^^^^^^^^
  File "/Users/kjaggav1/Library/CloudStorage/OneDrive-JCPenney/myworkspace/practice/foodclassification/.venv/lib/python3.12/site-packages/ensure/main.py", line 872, in __call__
    return_val = self.f(*args, **kwargs)
                 ^^^^^^^^^^^^^^^^^^^^^^^
  File "/Users/kjaggav1/Library/CloudStorage/OneDrive-JCPenney/myworkspace/practice/foodclassification/src/foodclassification/utils/common.py", line 20, in read_yaml
    except BoxValueError:
           ^^^^^^^^^^^^^
NameError: name 'BoxValueError' is not defined. Did you mean: 'ValueError'?
[2024-09-07 18:37:17,450: INFO: main: >>>>>> stage Data Ingestion stage started <<<<<<<<<]
[2024-09-07 18:37:17,451: ERROR: main: name 'logger' is not defined]
Traceback (most recent call last):
  File "/Users/kjaggav1/Library/CloudStorage/OneDrive-JCPenney/myworkspace/practice/foodclassification/main.py", line 11, in <module>
    obj.main()
  File "/Users/kjaggav1/Library/CloudStorage/OneDrive-JCPenney/myworkspace/practice/foodclassification/src/foodclassification/pipeline/stage_01_data_ingestion.py", line 12, in main
    config = ConfigurationManager()
             ^^^^^^^^^^^^^^^^^^^^^^
  File "/Users/kjaggav1/Library/CloudStorage/OneDrive-JCPenney/myworkspace/practice/foodclassification/src/foodclassification/config/configuration.py", line 11, in __init__
    self.config = read_yaml(config_filepath)
                  ^^^^^^^^^^^^^^^^^^^^^^^^^^
  File "/Users/kjaggav1/Library/CloudStorage/OneDrive-JCPenney/myworkspace/practice/foodclassification/.venv/lib/python3.12/site-packages/ensure/main.py", line 872, in __call__
    return_val = self.f(*args, **kwargs)
                 ^^^^^^^^^^^^^^^^^^^^^^^
  File "/Users/kjaggav1/Library/CloudStorage/OneDrive-JCPenney/myworkspace/practice/foodclassification/src/foodclassification/utils/common.py", line 23, in read_yaml
    raise e
  File "/Users/kjaggav1/Library/CloudStorage/OneDrive-JCPenney/myworkspace/practice/foodclassification/src/foodclassification/utils/common.py", line 18, in read_yaml
    logger.info(f"yaml file: {path_to_yaml} loaded successfully")
    ^^^^^^
NameError: name 'logger' is not defined
[2024-09-07 18:39:15,928: INFO: main: >>>>>> stage Data Ingestion stage started <<<<<<<<<]
[2024-09-07 18:39:15,928: INFO: common: yaml file: config/config.yaml loaded successfully]
[2024-09-07 18:39:15,929: INFO: common: yaml file: params.yaml loaded successfully]
[2024-09-07 18:39:15,930: INFO: common: created directory at: artifacts]
[2024-09-07 18:39:15,930: INFO: common: created directory at: artifacts/data_ingestion]
[2024-09-07 18:39:15,930: ERROR: main: "'ConfigBox' object has no attribute 'object_key'"]
Traceback (most recent call last):
  File "box/box.py", line 593, in box.box.Box.__getitem__
KeyError: 'object_key'

The above exception was the direct cause of the following exception:

Traceback (most recent call last):
  File "box/box.py", line 632, in box.box.Box.__getattr__
  File "box/box.py", line 620, in box.box.Box.__getitem__
box.exceptions.BoxKeyError: "'object_key'"

During handling of the above exception, another exception occurred:

Traceback (most recent call last):
  File "box/box.py", line 634, in box.box.Box.__getattr__
AttributeError: 'ConfigBox' object has no attribute 'object_key'

The above exception was the direct cause of the following exception:

Traceback (most recent call last):
  File "box/config_box.py", line 29, in box.config_box.ConfigBox.__getattr__
  File "box/box.py", line 648, in box.box.Box.__getattr__
box.exceptions.BoxKeyError: "'ConfigBox' object has no attribute 'object_key'"

During handling of the above exception, another exception occurred:

Traceback (most recent call last):
  File "box/box.py", line 593, in box.box.Box.__getitem__
KeyError: 'object_key'

The above exception was the direct cause of the following exception:

Traceback (most recent call last):
  File "box/box.py", line 632, in box.box.Box.__getattr__
  File "box/box.py", line 620, in box.box.Box.__getitem__
box.exceptions.BoxKeyError: "'object_key'"

During handling of the above exception, another exception occurred:

Traceback (most recent call last):
  File "box/box.py", line 634, in box.box.Box.__getattr__
AttributeError: 'ConfigBox' object has no attribute 'object_key'

The above exception was the direct cause of the following exception:

Traceback (most recent call last):
  File "/Users/kjaggav1/Library/CloudStorage/OneDrive-JCPenney/myworkspace/practice/foodclassification/main.py", line 11, in <module>
    obj.main()
  File "/Users/kjaggav1/Library/CloudStorage/OneDrive-JCPenney/myworkspace/practice/foodclassification/src/foodclassification/pipeline/stage_01_data_ingestion.py", line 13, in main
    data_ingestion_config = config.get_data_ingestion_config()
                            ^^^^^^^^^^^^^^^^^^^^^^^^^^^^^^^^^^
  File "/Users/kjaggav1/Library/CloudStorage/OneDrive-JCPenney/myworkspace/practice/foodclassification/src/foodclassification/config/configuration.py", line 24, in get_data_ingestion_config
    object_key=config.object_key,
               ^^^^^^^^^^^^^^^^^
  File "box/config_box.py", line 31, in box.config_box.ConfigBox.__getattr__
  File "box/box.py", line 648, in box.box.Box.__getattr__
box.exceptions.BoxKeyError: "'ConfigBox' object has no attribute 'object_key'"
[2024-09-07 18:46:21,418: INFO: main: >>>>>> stage Data Ingestion stage started <<<<<<<<<]
[2024-09-07 18:46:21,419: INFO: common: yaml file: config/config.yaml loaded successfully]
[2024-09-07 18:46:21,421: INFO: common: yaml file: params.yaml loaded successfully]
[2024-09-07 18:46:21,421: INFO: common: created directory at: artifacts]
[2024-09-07 18:46:21,422: INFO: common: created directory at: artifacts/data_ingestion]
[2024-09-07 18:46:21,422: ERROR: main: "'ConfigBox' object has no attribute 'bucket_name'"]
Traceback (most recent call last):
  File "box/box.py", line 593, in box.box.Box.__getitem__
KeyError: 'bucket_name'

The above exception was the direct cause of the following exception:

Traceback (most recent call last):
  File "box/box.py", line 632, in box.box.Box.__getattr__
  File "box/box.py", line 620, in box.box.Box.__getitem__
box.exceptions.BoxKeyError: "'bucket_name'"

During handling of the above exception, another exception occurred:

Traceback (most recent call last):
  File "box/box.py", line 634, in box.box.Box.__getattr__
AttributeError: 'ConfigBox' object has no attribute 'bucket_name'

The above exception was the direct cause of the following exception:

Traceback (most recent call last):
  File "box/config_box.py", line 29, in box.config_box.ConfigBox.__getattr__
  File "box/box.py", line 648, in box.box.Box.__getattr__
box.exceptions.BoxKeyError: "'ConfigBox' object has no attribute 'bucket_name'"

During handling of the above exception, another exception occurred:

Traceback (most recent call last):
  File "box/box.py", line 593, in box.box.Box.__getitem__
KeyError: 'bucket_name'

The above exception was the direct cause of the following exception:

Traceback (most recent call last):
  File "box/box.py", line 632, in box.box.Box.__getattr__
  File "box/box.py", line 620, in box.box.Box.__getitem__
box.exceptions.BoxKeyError: "'bucket_name'"

During handling of the above exception, another exception occurred:

Traceback (most recent call last):
  File "box/box.py", line 634, in box.box.Box.__getattr__
AttributeError: 'ConfigBox' object has no attribute 'bucket_name'

The above exception was the direct cause of the following exception:

Traceback (most recent call last):
  File "/Users/kjaggav1/Library/CloudStorage/OneDrive-JCPenney/myworkspace/practice/foodclassification/main.py", line 11, in <module>
    obj.main()
  File "/Users/kjaggav1/Library/CloudStorage/OneDrive-JCPenney/myworkspace/practice/foodclassification/src/foodclassification/pipeline/stage_01_data_ingestion.py", line 13, in main
    data_ingestion_config = config.get_data_ingestion_config()
                            ^^^^^^^^^^^^^^^^^^^^^^^^^^^^^^^^^^
  File "/Users/kjaggav1/Library/CloudStorage/OneDrive-JCPenney/myworkspace/practice/foodclassification/src/foodclassification/config/configuration.py", line 27, in get_data_ingestion_config
    bucket_name=config.bucket_name,
                ^^^^^^^^^^^^^^^^^^
  File "box/config_box.py", line 31, in box.config_box.ConfigBox.__getattr__
  File "box/box.py", line 648, in box.box.Box.__getattr__
box.exceptions.BoxKeyError: "'ConfigBox' object has no attribute 'bucket_name'"
[2024-09-07 18:47:18,567: INFO: main: >>>>>> stage Data Ingestion stage started <<<<<<<<<]
[2024-09-07 18:47:18,567: INFO: common: yaml file: config/config.yaml loaded successfully]
[2024-09-07 18:47:18,569: INFO: common: yaml file: params.yaml loaded successfully]
[2024-09-07 18:47:18,569: INFO: common: created directory at: artifacts]
[2024-09-07 18:47:18,569: INFO: common: created directory at: artifacts/data_ingestion]
[2024-09-07 18:47:18,569: ERROR: main: 'AWS_ACCESS_KEY_ID']
Traceback (most recent call last):
  File "/Users/kjaggav1/Library/CloudStorage/OneDrive-JCPenney/myworkspace/practice/foodclassification/main.py", line 11, in <module>
    obj.main()
  File "/Users/kjaggav1/Library/CloudStorage/OneDrive-JCPenney/myworkspace/practice/foodclassification/src/foodclassification/pipeline/stage_01_data_ingestion.py", line 13, in main
    data_ingestion_config = config.get_data_ingestion_config()
                            ^^^^^^^^^^^^^^^^^^^^^^^^^^^^^^^^^^
  File "/Users/kjaggav1/Library/CloudStorage/OneDrive-JCPenney/myworkspace/practice/foodclassification/src/foodclassification/config/configuration.py", line 28, in get_data_ingestion_config
    access_key=os.environ['AWS_ACCESS_KEY_ID'],
               ~~~~~~~~~~^^^^^^^^^^^^^^^^^^^^^
  File "<frozen os>", line 714, in __getitem__
KeyError: 'AWS_ACCESS_KEY_ID'
[2024-09-07 18:47:50,875: INFO: main: >>>>>> stage Data Ingestion stage started <<<<<<<<<]
[2024-09-07 18:47:50,875: INFO: common: yaml file: config/config.yaml loaded successfully]
[2024-09-07 18:47:50,876: INFO: common: yaml file: params.yaml loaded successfully]
[2024-09-07 18:47:50,877: INFO: common: created directory at: artifacts]
[2024-09-07 18:47:50,877: INFO: common: created directory at: artifacts/data_ingestion]
[2024-09-07 18:48:12,593: INFO: data_ingestion: File 'foodclassification.zip' downloaded to 'artifacts/data_ingestion/data.zip'.]
[2024-09-07 18:48:15,951: INFO: main: >>>>>> stage Data Ingestion stage completed <<<<<<<<

x==============x]
[2024-09-08 22:30:57,967: INFO: common: yaml file: config/config.yaml loaded successfully]
[2024-09-08 22:30:57,971: INFO: common: yaml file: params.yaml loaded successfully]
[2024-09-08 22:30:57,973: INFO: common: created directory at: artifacts]
[2024-09-08 22:30:57,974: INFO: common: created directory at: artifacts/prepare_base_model]
[2024-09-08 22:33:20,251: INFO: common: yaml file: config/config.yaml loaded successfully]
[2024-09-08 22:33:20,253: INFO: common: yaml file: params.yaml loaded successfully]
[2024-09-08 22:33:20,254: INFO: common: created directory at: artifacts]
[2024-09-08 22:33:20,254: INFO: common: created directory at: artifacts/prepare_base_model]
[2024-09-08 22:34:18,640: INFO: common: yaml file: config/config.yaml loaded successfully]
[2024-09-08 22:34:18,642: INFO: common: yaml file: params.yaml loaded successfully]
[2024-09-08 22:34:18,643: INFO: common: created directory at: artifacts]
[2024-09-08 22:34:18,643: INFO: common: created directory at: artifacts/prepare_base_model]
[2024-09-08 22:35:07,221: INFO: common: yaml file: config/config.yaml loaded successfully]
[2024-09-08 22:35:07,223: INFO: common: yaml file: params.yaml loaded successfully]
[2024-09-08 22:35:07,224: INFO: common: created directory at: artifacts]
[2024-09-08 22:35:07,224: INFO: common: created directory at: artifacts/prepare_base_model]
[2024-09-08 22:49:15,573: INFO: common: yaml file: config/config.yaml loaded successfully]
[2024-09-08 22:49:15,574: INFO: common: yaml file: params.yaml loaded successfully]
[2024-09-08 22:49:15,575: INFO: common: created directory at: artifacts]
[2024-09-08 22:49:15,575: INFO: common: created directory at: artifacts/prepare_base_model]
