[2024-09-02 08:52:12,706: INFO: main: This is use to test logging messages]
[2024-09-07 18:31:30,460: INFO: main: >>>>>> stage Data Ingestion stage started <<<<<<<<<]
[2024-09-07 18:31:30,461: ERROR: main: name 'BoxValueError' is not defined]
Traceback (most recent call last):
  File "/Users/kjaggav1/Library/CloudStorage/OneDrive-JCPenney/myworkspace/practice/foodclassification/src/foodclassification/utils/common.py", line 17, in read_yaml
    content = yaml.safe_load(yaml_file)
              ^^^^
NameError: name 'yaml' is not defined

During handling of the above exception, another exception occurred:

Traceback (most recent call last):
  File "/Users/kjaggav1/Library/CloudStorage/OneDrive-JCPenney/myworkspace/practice/foodclassification/main.py", line 11, in <module>
    obj.main()
  File "/Users/kjaggav1/Library/CloudStorage/OneDrive-JCPenney/myworkspace/practice/foodclassification/src/foodclassification/pipeline/stage_01_data_ingestion.py", line 12, in main
    config = ConfigurationManager()
             ^^^^^^^^^^^^^^^^^^^^^^
  File "/Users/kjaggav1/Library/CloudStorage/OneDrive-JCPenney/myworkspace/practice/foodclassification/src/foodclassification/config/configuration.py", line 11, in __init__
    self.config = read_yaml(config_filepath)
                  ^^^^^^^^^^^^^^^^^^^^^^^^^^
  File "/Users/kjaggav1/Library/CloudStorage/OneDrive-JCPenney/myworkspace/practice/foodclassification/.venv/lib/python3.12/site-packages/ensure/main.py", line 872, in __call__
    return_val = self.f(*args, **kwargs)
                 ^^^^^^^^^^^^^^^^^^^^^^^
  File "/Users/kjaggav1/Library/CloudStorage/OneDrive-JCPenney/myworkspace/practice/foodclassification/src/foodclassification/utils/common.py", line 20, in read_yaml
    except BoxValueError:
           ^^^^^^^^^^^^^
NameError: name 'BoxValueError' is not defined. Did you mean: 'ValueError'?
[2024-09-07 18:31:55,163: INFO: main: >>>>>> stage Data Ingestion stage started <<<<<<<<<]
[2024-09-07 18:31:55,163: ERROR: main: name 'BoxValueError' is not defined]
Traceback (most recent call last):
  File "/Users/kjaggav1/Library/CloudStorage/OneDrive-JCPenney/myworkspace/practice/foodclassification/src/foodclassification/utils/common.py", line 17, in read_yaml
    content = yaml.safe_load(yaml_file)
              ^^^^
NameError: name 'yaml' is not defined

During handling of the above exception, another exception occurred:

Traceback (most recent call last):
  File "/Users/kjaggav1/Library/CloudStorage/OneDrive-JCPenney/myworkspace/practice/foodclassification/main.py", line 11, in <module>
    obj.main()
  File "/Users/kjaggav1/Library/CloudStorage/OneDrive-JCPenney/myworkspace/practice/foodclassification/src/foodclassification/pipeline/stage_01_data_ingestion.py", line 12, in main
    config = ConfigurationManager()
             ^^^^^^^^^^^^^^^^^^^^^^
  File "/Users/kjaggav1/Library/CloudStorage/OneDrive-JCPenney/myworkspace/practice/foodclassification/src/foodclassification/config/configuration.py", line 11, in __init__
    self.config = read_yaml(config_filepath)
                  ^^^^^^^^^^^^^^^^^^^^^^^^^^
  File "/Users/kjaggav1/Library/CloudStorage/OneDrive-JCPenney/myworkspace/practice/foodclassification/.venv/lib/python3.12/site-packages/ensure/main.py", line 872, in __call__
    return_val = self.f(*args, **kwargs)
                 ^^^^^^^^^^^^^^^^^^^^^^^
  File "/Users/kjaggav1/Library/CloudStorage/OneDrive-JCPenney/myworkspace/practice/foodclassification/src/foodclassification/utils/common.py", line 20, in read_yaml
    except BoxValueError:
           ^^^^^^^^^^^^^
NameError: name 'BoxValueError' is not defined. Did you mean: 'ValueError'?
[2024-09-07 18:35:33,311: INFO: main: >>>>>> stage Data Ingestion stage started <<<<<<<<<]
[2024-09-07 18:35:33,311: ERROR: main: name 'BoxValueError' is not defined]
Traceback (most recent call last):
  File "/Users/kjaggav1/Library/CloudStorage/OneDrive-JCPenney/myworkspace/practice/foodclassification/src/foodclassification/utils/common.py", line 17, in read_yaml
    content = yaml.safe_load(yaml_file)
              ^^^^
NameError: name 'yaml' is not defined

During handling of the above exception, another exception occurred:

Traceback (most recent call last):
  File "/Users/kjaggav1/Library/CloudStorage/OneDrive-JCPenney/myworkspace/practice/foodclassification/main.py", line 11, in <module>
    obj.main()
  File "/Users/kjaggav1/Library/CloudStorage/OneDrive-JCPenney/myworkspace/practice/foodclassification/src/foodclassification/pipeline/stage_01_data_ingestion.py", line 12, in main
    config = ConfigurationManager()
             ^^^^^^^^^^^^^^^^^^^^^^
  File "/Users/kjaggav1/Library/CloudStorage/OneDrive-JCPenney/myworkspace/practice/foodclassification/src/foodclassification/config/configuration.py", line 11, in __init__
    self.config = read_yaml(config_filepath)
                  ^^^^^^^^^^^^^^^^^^^^^^^^^^
  File "/Users/kjaggav1/Library/CloudStorage/OneDrive-JCPenney/myworkspace/practice/foodclassification/.venv/lib/python3.12/site-packages/ensure/main.py", line 872, in __call__
    return_val = self.f(*args, **kwargs)
                 ^^^^^^^^^^^^^^^^^^^^^^^
  File "/Users/kjaggav1/Library/CloudStorage/OneDrive-JCPenney/myworkspace/practice/foodclassification/src/foodclassification/utils/common.py", line 20, in read_yaml
    except BoxValueError:
           ^^^^^^^^^^^^^
NameError: name 'BoxValueError' is not defined. Did you mean: 'ValueError'?
[2024-09-07 18:37:17,450: INFO: main: >>>>>> stage Data Ingestion stage started <<<<<<<<<]
[2024-09-07 18:37:17,451: ERROR: main: name 'logger' is not defined]
Traceback (most recent call last):
  File "/Users/kjaggav1/Library/CloudStorage/OneDrive-JCPenney/myworkspace/practice/foodclassification/main.py", line 11, in <module>
    obj.main()
  File "/Users/kjaggav1/Library/CloudStorage/OneDrive-JCPenney/myworkspace/practice/foodclassification/src/foodclassification/pipeline/stage_01_data_ingestion.py", line 12, in main
    config = ConfigurationManager()
             ^^^^^^^^^^^^^^^^^^^^^^
  File "/Users/kjaggav1/Library/CloudStorage/OneDrive-JCPenney/myworkspace/practice/foodclassification/src/foodclassification/config/configuration.py", line 11, in __init__
    self.config = read_yaml(config_filepath)
                  ^^^^^^^^^^^^^^^^^^^^^^^^^^
  File "/Users/kjaggav1/Library/CloudStorage/OneDrive-JCPenney/myworkspace/practice/foodclassification/.venv/lib/python3.12/site-packages/ensure/main.py", line 872, in __call__
    return_val = self.f(*args, **kwargs)
                 ^^^^^^^^^^^^^^^^^^^^^^^
  File "/Users/kjaggav1/Library/CloudStorage/OneDrive-JCPenney/myworkspace/practice/foodclassification/src/foodclassification/utils/common.py", line 23, in read_yaml
    raise e
  File "/Users/kjaggav1/Library/CloudStorage/OneDrive-JCPenney/myworkspace/practice/foodclassification/src/foodclassification/utils/common.py", line 18, in read_yaml
    logger.info(f"yaml file: {path_to_yaml} loaded successfully")
    ^^^^^^
NameError: name 'logger' is not defined
[2024-09-07 18:39:15,928: INFO: main: >>>>>> stage Data Ingestion stage started <<<<<<<<<]
[2024-09-07 18:39:15,928: INFO: common: yaml file: config/config.yaml loaded successfully]
[2024-09-07 18:39:15,929: INFO: common: yaml file: params.yaml loaded successfully]
[2024-09-07 18:39:15,930: INFO: common: created directory at: artifacts]
[2024-09-07 18:39:15,930: INFO: common: created directory at: artifacts/data_ingestion]
[2024-09-07 18:39:15,930: ERROR: main: "'ConfigBox' object has no attribute 'object_key'"]
Traceback (most recent call last):
  File "box/box.py", line 593, in box.box.Box.__getitem__
KeyError: 'object_key'

The above exception was the direct cause of the following exception:

Traceback (most recent call last):
  File "box/box.py", line 632, in box.box.Box.__getattr__
  File "box/box.py", line 620, in box.box.Box.__getitem__
box.exceptions.BoxKeyError: "'object_key'"

During handling of the above exception, another exception occurred:

Traceback (most recent call last):
  File "box/box.py", line 634, in box.box.Box.__getattr__
AttributeError: 'ConfigBox' object has no attribute 'object_key'

The above exception was the direct cause of the following exception:

Traceback (most recent call last):
  File "box/config_box.py", line 29, in box.config_box.ConfigBox.__getattr__
  File "box/box.py", line 648, in box.box.Box.__getattr__
box.exceptions.BoxKeyError: "'ConfigBox' object has no attribute 'object_key'"

During handling of the above exception, another exception occurred:

Traceback (most recent call last):
  File "box/box.py", line 593, in box.box.Box.__getitem__
KeyError: 'object_key'

The above exception was the direct cause of the following exception:

Traceback (most recent call last):
  File "box/box.py", line 632, in box.box.Box.__getattr__
  File "box/box.py", line 620, in box.box.Box.__getitem__
box.exceptions.BoxKeyError: "'object_key'"

During handling of the above exception, another exception occurred:

Traceback (most recent call last):
  File "box/box.py", line 634, in box.box.Box.__getattr__
AttributeError: 'ConfigBox' object has no attribute 'object_key'

The above exception was the direct cause of the following exception:

Traceback (most recent call last):
  File "/Users/kjaggav1/Library/CloudStorage/OneDrive-JCPenney/myworkspace/practice/foodclassification/main.py", line 11, in <module>
    obj.main()
  File "/Users/kjaggav1/Library/CloudStorage/OneDrive-JCPenney/myworkspace/practice/foodclassification/src/foodclassification/pipeline/stage_01_data_ingestion.py", line 13, in main
    data_ingestion_config = config.get_data_ingestion_config()
                            ^^^^^^^^^^^^^^^^^^^^^^^^^^^^^^^^^^
  File "/Users/kjaggav1/Library/CloudStorage/OneDrive-JCPenney/myworkspace/practice/foodclassification/src/foodclassification/config/configuration.py", line 24, in get_data_ingestion_config
    object_key=config.object_key,
               ^^^^^^^^^^^^^^^^^
  File "box/config_box.py", line 31, in box.config_box.ConfigBox.__getattr__
  File "box/box.py", line 648, in box.box.Box.__getattr__
box.exceptions.BoxKeyError: "'ConfigBox' object has no attribute 'object_key'"
[2024-09-07 18:46:21,418: INFO: main: >>>>>> stage Data Ingestion stage started <<<<<<<<<]
[2024-09-07 18:46:21,419: INFO: common: yaml file: config/config.yaml loaded successfully]
[2024-09-07 18:46:21,421: INFO: common: yaml file: params.yaml loaded successfully]
[2024-09-07 18:46:21,421: INFO: common: created directory at: artifacts]
[2024-09-07 18:46:21,422: INFO: common: created directory at: artifacts/data_ingestion]
[2024-09-07 18:46:21,422: ERROR: main: "'ConfigBox' object has no attribute 'bucket_name'"]
Traceback (most recent call last):
  File "box/box.py", line 593, in box.box.Box.__getitem__
KeyError: 'bucket_name'

The above exception was the direct cause of the following exception:

Traceback (most recent call last):
  File "box/box.py", line 632, in box.box.Box.__getattr__
  File "box/box.py", line 620, in box.box.Box.__getitem__
box.exceptions.BoxKeyError: "'bucket_name'"

During handling of the above exception, another exception occurred:

Traceback (most recent call last):
  File "box/box.py", line 634, in box.box.Box.__getattr__
AttributeError: 'ConfigBox' object has no attribute 'bucket_name'

The above exception was the direct cause of the following exception:

Traceback (most recent call last):
  File "box/config_box.py", line 29, in box.config_box.ConfigBox.__getattr__
  File "box/box.py", line 648, in box.box.Box.__getattr__
box.exceptions.BoxKeyError: "'ConfigBox' object has no attribute 'bucket_name'"

During handling of the above exception, another exception occurred:

Traceback (most recent call last):
  File "box/box.py", line 593, in box.box.Box.__getitem__
KeyError: 'bucket_name'

The above exception was the direct cause of the following exception:

Traceback (most recent call last):
  File "box/box.py", line 632, in box.box.Box.__getattr__
  File "box/box.py", line 620, in box.box.Box.__getitem__
box.exceptions.BoxKeyError: "'bucket_name'"

During handling of the above exception, another exception occurred:

Traceback (most recent call last):
  File "box/box.py", line 634, in box.box.Box.__getattr__
AttributeError: 'ConfigBox' object has no attribute 'bucket_name'

The above exception was the direct cause of the following exception:

Traceback (most recent call last):
  File "/Users/kjaggav1/Library/CloudStorage/OneDrive-JCPenney/myworkspace/practice/foodclassification/main.py", line 11, in <module>
    obj.main()
  File "/Users/kjaggav1/Library/CloudStorage/OneDrive-JCPenney/myworkspace/practice/foodclassification/src/foodclassification/pipeline/stage_01_data_ingestion.py", line 13, in main
    data_ingestion_config = config.get_data_ingestion_config()
                            ^^^^^^^^^^^^^^^^^^^^^^^^^^^^^^^^^^
  File "/Users/kjaggav1/Library/CloudStorage/OneDrive-JCPenney/myworkspace/practice/foodclassification/src/foodclassification/config/configuration.py", line 27, in get_data_ingestion_config
    bucket_name=config.bucket_name,
                ^^^^^^^^^^^^^^^^^^
  File "box/config_box.py", line 31, in box.config_box.ConfigBox.__getattr__
  File "box/box.py", line 648, in box.box.Box.__getattr__
box.exceptions.BoxKeyError: "'ConfigBox' object has no attribute 'bucket_name'"
[2024-09-07 18:47:18,567: INFO: main: >>>>>> stage Data Ingestion stage started <<<<<<<<<]
[2024-09-07 18:47:18,567: INFO: common: yaml file: config/config.yaml loaded successfully]
[2024-09-07 18:47:18,569: INFO: common: yaml file: params.yaml loaded successfully]
[2024-09-07 18:47:18,569: INFO: common: created directory at: artifacts]
[2024-09-07 18:47:18,569: INFO: common: created directory at: artifacts/data_ingestion]
[2024-09-07 18:47:18,569: ERROR: main: 'AWS_ACCESS_KEY_ID']
Traceback (most recent call last):
  File "/Users/kjaggav1/Library/CloudStorage/OneDrive-JCPenney/myworkspace/practice/foodclassification/main.py", line 11, in <module>
    obj.main()
  File "/Users/kjaggav1/Library/CloudStorage/OneDrive-JCPenney/myworkspace/practice/foodclassification/src/foodclassification/pipeline/stage_01_data_ingestion.py", line 13, in main
    data_ingestion_config = config.get_data_ingestion_config()
                            ^^^^^^^^^^^^^^^^^^^^^^^^^^^^^^^^^^
  File "/Users/kjaggav1/Library/CloudStorage/OneDrive-JCPenney/myworkspace/practice/foodclassification/src/foodclassification/config/configuration.py", line 28, in get_data_ingestion_config
    access_key=os.environ['AWS_ACCESS_KEY_ID'],
               ~~~~~~~~~~^^^^^^^^^^^^^^^^^^^^^
  File "<frozen os>", line 714, in __getitem__
KeyError: 'AWS_ACCESS_KEY_ID'
[2024-09-07 18:47:50,875: INFO: main: >>>>>> stage Data Ingestion stage started <<<<<<<<<]
[2024-09-07 18:47:50,875: INFO: common: yaml file: config/config.yaml loaded successfully]
[2024-09-07 18:47:50,876: INFO: common: yaml file: params.yaml loaded successfully]
[2024-09-07 18:47:50,877: INFO: common: created directory at: artifacts]
[2024-09-07 18:47:50,877: INFO: common: created directory at: artifacts/data_ingestion]
[2024-09-07 18:48:12,593: INFO: data_ingestion: File 'foodclassification.zip' downloaded to 'artifacts/data_ingestion/data.zip'.]
[2024-09-07 18:48:15,951: INFO: main: >>>>>> stage Data Ingestion stage completed <<<<<<<<

x==============x]
[2024-09-08 22:30:57,967: INFO: common: yaml file: config/config.yaml loaded successfully]
[2024-09-08 22:30:57,971: INFO: common: yaml file: params.yaml loaded successfully]
[2024-09-08 22:30:57,973: INFO: common: created directory at: artifacts]
[2024-09-08 22:30:57,974: INFO: common: created directory at: artifacts/prepare_base_model]
[2024-09-08 22:33:20,251: INFO: common: yaml file: config/config.yaml loaded successfully]
[2024-09-08 22:33:20,253: INFO: common: yaml file: params.yaml loaded successfully]
[2024-09-08 22:33:20,254: INFO: common: created directory at: artifacts]
[2024-09-08 22:33:20,254: INFO: common: created directory at: artifacts/prepare_base_model]
[2024-09-08 22:34:18,640: INFO: common: yaml file: config/config.yaml loaded successfully]
[2024-09-08 22:34:18,642: INFO: common: yaml file: params.yaml loaded successfully]
[2024-09-08 22:34:18,643: INFO: common: created directory at: artifacts]
[2024-09-08 22:34:18,643: INFO: common: created directory at: artifacts/prepare_base_model]
[2024-09-08 22:35:07,221: INFO: common: yaml file: config/config.yaml loaded successfully]
[2024-09-08 22:35:07,223: INFO: common: yaml file: params.yaml loaded successfully]
[2024-09-08 22:35:07,224: INFO: common: created directory at: artifacts]
[2024-09-08 22:35:07,224: INFO: common: created directory at: artifacts/prepare_base_model]
[2024-09-08 22:49:15,573: INFO: common: yaml file: config/config.yaml loaded successfully]
[2024-09-08 22:49:15,574: INFO: common: yaml file: params.yaml loaded successfully]
[2024-09-08 22:49:15,575: INFO: common: created directory at: artifacts]
[2024-09-08 22:49:15,575: INFO: common: created directory at: artifacts/prepare_base_model]
[2024-09-09 15:28:41,832: INFO: common: yaml file: config/config.yaml loaded successfully]
[2024-09-09 15:28:41,833: INFO: common: yaml file: params.yaml loaded successfully]
[2024-09-09 15:28:41,834: INFO: common: created directory at: artifacts]
[2024-09-09 15:28:41,834: INFO: common: created directory at: artifacts/prepare_base_model]
[2024-09-09 15:28:42,008: WARNING: saving_api: You are saving your model as an HDF5 file via `model.save()` or `keras.saving.save_model(model)`. This file format is considered legacy. We recommend using instead the native Keras format, e.g. `model.save('my_model.keras')` or `keras.saving.save_model(model, 'my_model.keras')`. ]
[2024-09-09 15:28:42,065: WARNING: saving_api: You are saving your model as an HDF5 file via `model.save()` or `keras.saving.save_model(model)`. This file format is considered legacy. We recommend using instead the native Keras format, e.g. `model.save('my_model.keras')` or `keras.saving.save_model(model, 'my_model.keras')`. ]
[2024-09-09 23:12:16,879: INFO: main: >>>>>> stage Data Ingestion stage started <<<<<<<<<]
[2024-09-09 23:12:16,882: INFO: common: yaml file: config/config.yaml loaded successfully]
[2024-09-09 23:12:16,883: INFO: common: yaml file: params.yaml loaded successfully]
[2024-09-09 23:12:16,883: INFO: common: created directory at: artifacts]
[2024-09-09 23:12:16,883: INFO: common: created directory at: artifacts/data_ingestion]
[2024-09-09 23:12:43,111: INFO: data_ingestion: File 'foodclassification.zip' downloaded to 'artifacts/data_ingestion/data.zip'.]
[2024-09-09 23:12:47,522: INFO: main: >>>>>> stage Data Ingestion stage completed <<<<<<<<

x==============x]
[2024-09-09 23:12:47,522: INFO: main: ***************************]
[2024-09-09 23:12:47,523: INFO: main: >>>>>>>> stage Prepare base model started <<<<<<<<<<]
[2024-09-09 23:12:47,523: INFO: common: yaml file: config/config.yaml loaded successfully]
[2024-09-09 23:12:47,524: INFO: common: yaml file: params.yaml loaded successfully]
[2024-09-09 23:12:47,524: INFO: common: created directory at: artifacts]
[2024-09-09 23:12:47,524: INFO: common: created directory at: artifacts/prepare_base_model]
[2024-09-09 23:12:47,734: WARNING: saving_api: You are saving your model as an HDF5 file via `model.save()` or `keras.saving.save_model(model)`. This file format is considered legacy. We recommend using instead the native Keras format, e.g. `model.save('my_model.keras')` or `keras.saving.save_model(model, 'my_model.keras')`. ]
[2024-09-09 23:12:47,808: WARNING: saving_api: You are saving your model as an HDF5 file via `model.save()` or `keras.saving.save_model(model)`. This file format is considered legacy. We recommend using instead the native Keras format, e.g. `model.save('my_model.keras')` or `keras.saving.save_model(model, 'my_model.keras')`. ]
[2024-09-09 23:12:47,864: INFO: main: >>>>>>>> stage Prepare base model completed <<<<<<

x===============x]
[2024-09-10 07:21:17,500: INFO: common: yaml file: config/config.yaml loaded successfully]
[2024-09-10 07:21:17,502: INFO: common: yaml file: params.yaml loaded successfully]
[2024-09-10 07:21:17,503: INFO: common: created directory at: artifacts]
[2024-09-10 21:14:49,345: INFO: main: >>>>>> stage Data Ingestion stage started <<<<<<<<<]
[2024-09-10 21:14:49,346: INFO: common: yaml file: config/config.yaml loaded successfully]
[2024-09-10 21:14:49,347: INFO: common: yaml file: params.yaml loaded successfully]
[2024-09-10 21:14:49,347: INFO: common: created directory at: artifacts]
[2024-09-10 21:14:49,347: INFO: common: created directory at: artifacts/data_ingestion]
[2024-09-10 21:14:49,348: INFO: data_ingestion: file already present of size: ~ 771248 KB]
[2024-09-10 21:14:53,836: INFO: main: >>>>>> stage Data Ingestion stage completed <<<<<<<<

x==============x]
[2024-09-10 21:14:53,836: INFO: main: ***************************]
[2024-09-10 21:14:53,836: INFO: main: >>>>>>>> stage Prepare base model started <<<<<<<<<<]
[2024-09-10 21:14:53,837: INFO: common: yaml file: config/config.yaml loaded successfully]
[2024-09-10 21:14:53,838: INFO: common: yaml file: params.yaml loaded successfully]
[2024-09-10 21:14:53,838: INFO: common: created directory at: artifacts]
[2024-09-10 21:14:53,838: INFO: common: created directory at: artifacts/prepare_base_model]
[2024-09-10 21:14:54,086: WARNING: saving_api: You are saving your model as an HDF5 file via `model.save()` or `keras.saving.save_model(model)`. This file format is considered legacy. We recommend using instead the native Keras format, e.g. `model.save('my_model.keras')` or `keras.saving.save_model(model, 'my_model.keras')`. ]
[2024-09-10 21:14:54,141: WARNING: saving_api: You are saving your model as an HDF5 file via `model.save()` or `keras.saving.save_model(model)`. This file format is considered legacy. We recommend using instead the native Keras format, e.g. `model.save('my_model.keras')` or `keras.saving.save_model(model, 'my_model.keras')`. ]
[2024-09-10 21:14:54,187: INFO: main: >>>>>>>> stage Prepare base model completed <<<<<<

x===============x]
[2024-09-10 21:16:13,227: INFO: common: yaml file: config/config.yaml loaded successfully]
[2024-09-10 21:16:13,229: INFO: common: yaml file: params.yaml loaded successfully]
[2024-09-10 21:16:13,230: INFO: common: created directory at: artifacts]
[2024-09-10 21:16:54,857: INFO: common: yaml file: config/config.yaml loaded successfully]
[2024-09-10 21:16:54,860: INFO: common: yaml file: params.yaml loaded successfully]
[2024-09-10 21:16:54,861: INFO: common: created directory at: artifacts]
[2024-09-10 21:34:53,977: INFO: common: yaml file: config/config.yaml loaded successfully]
[2024-09-10 21:34:53,980: INFO: common: yaml file: params.yaml loaded successfully]
[2024-09-10 21:34:53,980: INFO: common: created directory at: artifacts]
[2024-09-10 21:41:21,557: INFO: common: yaml file: config/config.yaml loaded successfully]
[2024-09-10 21:41:21,575: INFO: common: yaml file: params.yaml loaded successfully]
[2024-09-10 21:41:21,576: INFO: common: created directory at: artifacts]
[2024-09-10 21:41:21,577: INFO: common: created directory at: artifacts/prepare_callbacks/checkpoint_dir]
[2024-09-10 21:41:21,577: INFO: common: created directory at: artifacts/prepare_callbacks/tensorboard_log_dir]
[2024-09-10 21:42:05,410: INFO: common: yaml file: config/config.yaml loaded successfully]
[2024-09-10 21:42:05,413: INFO: common: yaml file: params.yaml loaded successfully]
[2024-09-10 21:42:05,414: INFO: common: created directory at: artifacts]
[2024-09-10 21:42:05,415: INFO: common: created directory at: artifacts/prepare_callbacks/checkpoint_dir]
[2024-09-10 21:42:05,416: INFO: common: created directory at: artifacts/prepare_callbacks/tensorboard_log_dir]
[2024-09-10 21:45:12,784: INFO: common: yaml file: config/config.yaml loaded successfully]
[2024-09-10 21:45:12,788: INFO: common: yaml file: params.yaml loaded successfully]
[2024-09-10 21:45:12,789: INFO: common: created directory at: artifacts]
[2024-09-10 21:45:12,790: INFO: common: created directory at: artifacts/prepare_callbacks/checkpoint_dir]
[2024-09-10 21:45:12,791: INFO: common: created directory at: artifacts/prepare_callbacks/tensorboard_log_dir]
